Workbook

Sheet Summary
B1: Detail_CDN | C1: Detail_HPM | D1: Detail_ITC | E1: Detail_Shared | F1: Detail_MSK | G1: Detail_TDM | H1: Detail_Sinsen | I1: Detail_TRIO | J1: Detail_Anper | K1: Detail_MenaragAgung
A2: Total Unit Price | B2: =SUM(Detail_CDN!X2:X50000) -> 0 | C2: =SUM(Detail_HPM!X2:X50000) -> 0 | D2: =SUM(Detail_ITC!X2:X50000) -> 0 | E2: =SUM(Detail_Shared!X2:X50000) -> 0 | F2: =SUM(Detail_MSK!X2:X50000) -> 0 | G2: =SUM(Detail_TDM!X2:X50000) -> 0 | H2: =SUM(Detail_Sinsen!X2:X50000) -> 0 | I2: =SUM(Detail_TRIO!X2:X50000) -> 0 | J2: =SUM(Detail_Anper!X2:X50000) -> 0 | K2: =SUM(Detail_MenaraAgung!X2:X50000) -> 0 | L2: =SUM(B2:K2) -> 0
A3: Total | B3: =SUM(Detail_CDN!W2:W50000) -> 29137510 | C3: =SUM(Detail_HPM!W2:W50000) -> 19604596 | D3: =SUM(Detail_ITC!W2:W50000) -> 19340848 | E3: =SUM(Detail_Shared!W2:W50000) -> 73374532 | F3: =SUM(Detail_MSK!W2:W50000) -> 18166394 | G3: =SUM(Detail_TDM!W2:W50000) -> 20497324 | H3: =SUM(Detail_Sinsen!W2:W50000) -> 22195146 | I3: =SUM(Detail_TRIO!W2:W50000) -> 22999195 | J3: =SUM(Detail_Anper!W2:W50000) -> 18960517 | K3: =SUM(Detail_MenaraAgung!W2:W50000) -> 19080853 | L3: =SUM(B3:K3) -> 2.6335691e+08

Sheet Detail_CDN
A1: Period | B1: Agreement Name | C1: Company Name | D1: Tenant Primary Domain | E1: Publisher Subscription ID | F1: Publisher Subscription Name | G1: Product ID | H1: Product Name | I1: Category | J1: Subcategory | K1: Meter Name | L1: Usage Start Date | M1: Usage End Date | N1: Quantity | O1: Unit | P1: Currency | Q1: Resource Group Name | R1: Resource Name | S1: Location | T1: Tags_JSON | U1: Tags_KeyValue | V1: Tags_Count | W1: Total
A2: May | B2: Microsoft CSP Azure Plan | C2: Divisi Inovasi | D2: divisiinovasi.onmicrosoft.com | E2: a4cdaa2e-caa7-440f-b849-928a3ceb7e31 | F2: AzureCSP_DivisiInovasi | G2: 1141685 | H2: Rtn Pref: MGN | I2: Bandwidth | J2: Rtn Preference: MGN | K2: Standard Data Transfer Out | L2: 46143 | M2: 46173 | N2: 0.077821913 | O2: 1 GB | P2: IDR | Q2: mc_rg-cantaloupe_cantaloupe_southeastasia | R2: aks-usereph2-16230473-vmss | S2: southeastasia | T2: { "Organization Name": "PT Nawa Darsana Teknologi", "Publisher": "Microsoft", "Publisher Customer ID": "346fa229-7c19-44ef-85c6-29e00edf66cf", "Unit Price": "1842.2975999933", "ERP": "162.921730257", "BenefitType": "Charge", "aks-managed-consolidated-additional-properties": "92c2fdef-4961-11f1-8cae-6277d8c8ca4f", "aks-managed-creationSource": "vmssclient-aks-usereph2-16230473-vmss", "aks-managed-enable-imds-restriction": "False", "aks-managed-kubeletIdentityClientID": "c5826f94-ec98-4f18-bd56-3490380ef971", "aks-managed-operationID": "585b1141-b235-488b-ae08-5da114d23dfb", "aks-managed-orchestrator": "Kubernetes:1.33.5", "aks-managed-poolName": "usereph2", "aks-managed-resourceNameSuffix": "40247467.0", "aks-managed-ssh-access": "LocalUser", "compute.aks.billing": "linux" } | U2: Organization Name=PT Nawa Darsana Teknologi; Publisher=Microsoft; Publisher Customer ID=346fa229-7c19-44ef-85c6-29e00edf66cf; Unit Price=1842.2975999933; ERP=162.921730257; BenefitType=Charge; aks-managed-consolidated-additional-properties=92c2fdef-4961-11f1-8cae-6277d8c8ca4f; aks-managed-creationSource=vmssclient-aks-usereph2-16230473-vmss; aks-managed-enable-imds-restriction=False; aks-managed-kubeletIdentityClientID=c5826f94-ec98-4f18-bd56-3490380ef971; aks-managed-operationID=585b1141-b235-488b-ae08-5da114d23dfb; aks-managed-orchestrator=Kubernetes:1.33.5; aks-managed-poolName=usereph2; aks-managed-resourceNameSuffix=40247467.0; aks-managed-ssh-access=LocalUser; compute.aks.billing=linux | V2: 16 | W2: 162.92112
A3: May | B3: Microsoft CSP Azure Plan | C3: Divisi Inovasi | D3: divisiinovasi.onmicrosoft.com | E3: a4cdaa2e-caa7-440f-b849-928a3ceb7e31 | F3: AzureCSP_DivisiInovasi | G3: 1141685 | H3: VM RI | I3: Virtual Machines | J3: Virtual Machines RI | K3: Standard | L3: 46143 | M3: 46173 | N3: 1 | O3: 1 Hour | P3: IDR | Q3: MC_RG-CANTALOUPE_CANTALOUPE_SOUTHEASTASIA | R3: aks-usereph2-16230473-vmss | S3: southeastasia | T3: { "Organization Name": "PT Nawa Darsana Teknologi", "Publisher": "Microsoft", "Publisher Customer ID": "346fa229-7c19-44ef-85c6-29e00edf66cf", "Unit Price": "0.0", "ERP": "0.0", "BenefitType": "Charge", "aks-managed-consolidated-additional-properties": "92c2fdef-4961-11f1-8cae-6277d8c8ca4f", "aks-managed-creationSource": "vmssclient-aks-usereph2-16230473-vmss", "aks-managed-enable-imds-restriction": "False", "aks-managed-kubeletIdentityClientID": "c5826f94-ec98-4f18-bd56-3490380ef971", "aks-managed-operationID": "585b1141-b235-488b-ae08-5da114d23dfb", "aks-managed-orchestrator": "Kubernetes:1.33.5", "aks-managed-poolName": "usereph2", "aks-managed-resourceNameSuffix": "40247467.0", "aks-managed-ssh-access": "LocalUser", "compute.aks.billing": "linux" } | U3: Organization Name=PT Nawa Darsana Teknologi; Publisher=Microsoft; Publisher Customer ID=346fa229-7c19-44ef-85c6-29e00edf66cf; Unit Price=0.0; ERP=0.0; BenefitType=Charge; aks-managed-consolidated-additional-properties=92c2fdef-4961-11f1-8cae-6277d8c8ca4f; aks-managed-creationSource=vmssclient-aks-usereph2-16230473-vmss; aks-managed-enable-imds-restriction=False; aks-managed-kubeletIdentityClientID=c5826f94-ec98-4f18-bd56-3490380ef971; aks-managed-operationID=585b1141-b235-488b-ae08-5da114d23dfb; aks-managed-orchestrator=Kubernetes:1.33.5; aks-managed-poolName=usereph2; aks-managed-resourceNameSuffix=40247467.0; aks-managed-ssh-access=LocalUser; compute.aks.billing=linux | V3: 16 | W3: 0
A4: May | B4: Microsoft CSP Azure Plan | C4: Divisi Inovasi | D4: divisiinovasi.onmicrosoft.com | E4: a4cdaa2e-caa7-440f-b849-928a3ceb7e31 | F4: AzureCSP_DivisiInovasi | G4: 1141685 | H4: VM RI | I4: Virtual Machines | J4: Virtual Machines RI | K4: Standard | L4: 46143 | M4: 46173 | N4: 21.134262 | O4: 1 Hour | P4: IDR | Q4: MC_RG-CANTALOUPE_CANTALOUPE_SOUTHEASTASIA | R4: aks-usereph2-16230473-vmss | S4: southeastasia | T4: { "Organization Name": "PT Nawa Darsana Teknologi", "Publisher": "Microsoft", "Publisher Customer ID": "346fa229-7c19-44ef-85c6-29e00edf66cf", "Unit Price": "0.0", "ERP": "0.0", "BenefitType": "Charge", "aks-managed-consolidated-additional-properties": "92c2fdef-4961-11f1-8cae-6277d8c8ca4f", "aks-managed-creationSource": "vmssclient-aks-usereph2-16230473-vmss", "aks-managed-enable-imds-restriction": "False", "aks-managed-kubeletIdentityClientID": "c5826f94-ec98-4f18-bd56-3490380ef971", "aks-managed-operationID": "585b1141-b235-488b-ae08-5da114d23dfb", "aks-managed-orchestrator": "Kubernetes:1.33.5", "aks-managed-poolName": "usereph2", "aks-managed-resourceNameSuffix": "40247467.0", "aks-managed-ssh-access": "LocalUser", "compute.aks.billing": "linux" } | U4: Organization Name=PT Nawa Darsana Teknologi; Publisher=Microsoft; Publisher Customer ID=346fa229-7c19-44ef-85c6-29e00edf66cf; Unit Price=0.0; ERP=0.0; BenefitType=Charge; aks-managed-consolidated-additional-properties=92c2fdef-4961-11f1-8cae-6277d8c8ca4f; aks-managed-creationSource=vmssclient-aks-usereph2-16230473-vmss; aks-managed-enable-imds-restriction=False; aks-managed-kubeletIdentityClientID=c5826f94-ec98-4f18-bd56-3490380ef971; aks-managed-operationID=585b1141-b235-488b-ae08-5da114d23dfb; aks-managed-orchestrator=Kubernetes:1.33.5; aks-managed-poolName=usereph2; aks-managed-resourceNameSuffix=40247467.0; aks-managed-ssh-access=LocalUser; compute.aks.billing=linux | V4: 16 | W4: 0
A5: May | B5: Microsoft CSP Azure Plan | C5: Divisi Inovasi | D5: divisiinovasi.onmicrosoft.com | E5: a4cdaa2e-caa7-440f-b849-928a3ceb7e31 | F5: AzureCSP_DivisiInovasi | G5: 1141685 | H5: VM RI | I5: Virtual Machines | J5: Virtual Machines RI | K5: Standard | L5: 46143 | M5: 46173 | N5: 0.183125 | O5: 1 Hour | P5: IDR | Q5: MC_RG-CANTALOUPE_CANTALOUPE_SOUTHEASTASIA | R5: aks-usereph2-16230473-vmss | S5: southeastasia | T5: { "Organization Name": "PT Nawa Darsana Teknologi", "Publisher": "Microsoft", "Publisher Customer ID": "346fa229-7c19-44ef-85c6-29e00edf66cf", "Unit Price": "0.0", "ERP": "0.0", "BenefitType": "Charge", "aks-managed-consolidated-additional-properties": "92c2fdef-4961-11f1-8cae-6277d8c8ca4f", "aks-managed-creationSource": "vmssclient-aks-usereph2-16230473-vmss", "aks-managed-enable-imds-restriction": "False", "aks-managed-kubeletIdentityClientID": "c5826f94-ec98-4f18-bd56-3490380ef971", "aks-managed-operationID": "585b1141-b235-488b-ae08-5da114d23dfb", "aks-managed-orchestrator": "Kubernetes:1.33.5", "aks-managed-poolName": "usereph2", "aks-managed-resourceNameSuffix": "40247467.0", "aks-managed-ssh-access": "LocalUser", "compute.aks.billing": "linux" } | U5: Organization Name=PT Nawa Darsana Teknologi; Publisher=Microsoft; Publisher Customer ID=346fa229-7c19-44ef-85c6-29e00edf66cf; Unit Price=0.0; ERP=0.0; BenefitType=Charge; aks-managed-consolidated-additional-properties=92c2fdef-4961-11f1-8cae-6277d8c8ca4f; aks-managed-creationSource=vmssclient-aks-usereph2-16230473-vmss; aks-managed-enable-imds-restriction=False; aks-managed-kubeletIdentityClientID=c5826f94-ec98-4f18-bd56-3490380ef971; aks-managed-operationID=585b1141-b235-488b-ae08-5da114d23dfb; aks-managed-orchestrator=Kubernetes:1.33.5; aks-managed-poolName=usereph2; aks-managed-resourceNameSuffix=40247467.0; aks-managed-ssh-access=LocalUser; compute.aks.billing=linux | V5: 16 | W5: 0
A6: May | B6: Microsoft CSP Azure Plan | C6: Divisi Inovasi | D6: divisiinovasi.onmicrosoft.com | E6: a4cdaa2e-caa7-440f-b849-928a3ceb7e31 | F6: AzureCSP_DivisiInovasi | G6: 1141685 | H6: VM RI | I6: Virtual Machines | J6: Virtual Machines RI | K6: Standard | L6: 46143 | M6: 46173 | N6: 1.733227 | O6: 1 Hour | P6: IDR | Q6: MC_RG-CANTALOUPE_CANTALOUPE_SOUTHEASTASIA | R6: aks-usereph2-16230473-vmss | S6: southeastasia | T6: { "Organization Name": "PT Nawa Darsana Teknologi", "Publisher": "Microsoft", "Publisher Customer ID": "346fa229-7c19-44ef-85c6-29e00edf66cf", "Unit Price": "0.0", "ERP": "0.0", "BenefitType": "Charge", "aks-managed-consolidated-additional-properties": "92c2fdef-4961-11f1-8cae-6277d8c8ca4f", "aks-managed-creationSource": "vmssclient-aks-usereph2-16230473-vmss", "aks-managed-enable-imds-restriction": "False", "aks-managed-kubeletIdentityClientID": "c5826f94-ec98-4f18-bd56-3490380ef971", "aks-managed-operationID": "585b1141-b235-488b-ae08-5da114d23dfb", "aks-managed-orchestrator": "Kubernetes:1.33.5", "aks-managed-poolName": "usereph2", "aks-managed-resourceNameSuffix": "40247467.0", "aks-managed-ssh-access": "LocalUser", "compute.aks.billing": "linux" } | U6: Organization Name=PT Nawa Darsana Teknologi; Publisher=Microsoft; Publisher Customer ID=346fa229-7c19-44ef-85c6-29e00edf66cf; Unit Price=0.0; ERP=0.0; BenefitType=Charge; aks-managed-consolidated-additional-properties=92c2fdef-4961-11f1-8cae-6277d8c8ca4f; aks-managed-creationSource=vmssclient-aks-usereph2-16230473-vmss; aks-managed-enable-imds-restriction=False; aks-managed-kubeletIdentityClientID=c5826f94-ec98-4f18-bd56-3490380ef971; aks-managed-operationID=585b1141-b235-488b-ae08-5da114d23dfb; aks-managed-orchestrator=Kubernetes:1.33.5; aks-managed-poolName=usereph2; aks-managed-resourceNameSuffix=40247467.0; aks-managed-ssh-access=LocalUser; compute.aks.billing=linux | V6: 16 | W6: 0
A7: May | B7: Microsoft CSP Azure Plan | C7: Divisi Inovasi | D7: divisiinovasi.onmicrosoft.com | E7: a4cdaa2e-caa7-440f-b849-928a3ceb7e31 | F7: AzureCSP_DivisiInovasi | G7: 1141685 | H7: VM RI | I7: Virtual Machines | J7: Virtual Machines RI | K7: Standard | L7: 46143 | M7: 46173 | N7: 0.533486 | O7: 1 Hour | P7: IDR | Q7: MC_RG-CANTALOUPE_CANTALOUPE_SOUTHEASTASIA | R7: aks-usereph2-16230473-vmss | S7: southeastasia | T7: { "Organization Name": "PT Nawa Darsana Teknologi", "Publisher": "Microsoft", "Publisher Customer ID": "346fa229-7c19-44ef-85c6-29e00edf66cf", "Unit Price": "0.0", "ERP": "0.0", "BenefitType": "Charge", "aks-managed-consolidated-additional-properties": "92c2fdef-4961-11f1-8cae-6277d8c8ca4f", "aks-managed-creationSource": "vmssclient-aks-usereph2-16230473-vmss", "aks-managed-enable-imds-restriction": "False", "aks-managed-kubeletIdentityClientID": "c5826f94-ec98-4f18-bd56-3490380ef971", "aks-managed-operationID": "585b1141-b235-488b-ae08-5da114d23dfb", "aks-managed-orchestrator": "Kubernetes:1.33.5", "aks-managed-poolName": "usereph2", "aks-managed-resourceNameSuffix": "40247467.0", "aks-managed-ssh-access": "LocalUser", "compute.aks.billing": "linux" } | U7: Organization Name=PT Nawa Darsana Teknologi; Publisher=Microsoft; Publisher Customer ID=346fa229-7c19-44ef-85c6-29e00edf66cf; Unit Price=0.0; ERP=0.0; BenefitType=Charge; aks-managed-consolidated-additional-properties=92c2fdef-4961-11f1-8cae-6277d8c8ca4f; aks-managed-creationSource=vmssclient-aks-usereph2-16230473-vmss; aks-managed-enable-imds-restriction=False; aks-managed-kubeletIdentityClientID=c5826f94-ec98-4f18-bd56-3490380ef971; aks-managed-operationID=585b1141-b235-488b-ae08-5da114d23dfb; aks-managed-orchestrator=Kubernetes:1.33.5; aks-managed-poolName=usereph2; aks-managed-resourceNameSuffix=40247467.0; aks-managed-ssh-access=LocalUser; compute.aks.billing=linux | V7: 16 | W7: 0
A8: May | B8: Microsoft CSP Azure Plan | C8: Divisi Inovasi | D8: divisiinovasi.onmicrosoft.com | E8: a4cdaa2e-caa7-440f-b849-928a3ceb7e31 | F8: AzureCSP_DivisiInovasi | G8: 1141685 | H8: VM RI | I8: Virtual Machines | J8: Virtual Machines RI | K8: Standard | L8: 46143 | M8: 46173 | N8: 0.16647 | O8: 1 Hour | P8: IDR | Q8: MC_RG-CANTALOUPE_CANTALOUPE_SOUTHEASTASIA | R8: aks-systemeph-85241862-vmss | S8: southeastasia | T8: { "Organization Name": "PT Nawa Darsana Teknologi", "Publisher": "Microsoft", "Publisher Customer ID": "346fa229-7c19-44ef-85c6-29e00edf66cf", "Unit Price": "0.0", "ERP": "0.0", "BenefitType": "Charge", "aks-managed-consolidated-additional-properties": "92c34f68-4961-11f1-8cae-6277d8c8ca4f", "aks-managed-creationSource": "vmssclient-aks-systemeph-85241862-vmss", "aks-managed-enable-imds-restriction": "False", "aks-managed-kubeletIdentityClientID": "c5826f94-ec98-4f18-bd56-3490380ef971", "aks-managed-operationID": "585b1141-b235-488b-ae08-5da114d23dfb", "aks-managed-orchestrator": "Kubernetes:1.33.5", "aks-managed-poolName": "systemeph", "aks-managed-resourceNameSuffix": "40247467.0", "aks-managed-ssh-access": "LocalUser", "compute.aks.billing": "linux" } | U8: Organization Name=PT Nawa Darsana Teknologi; Publisher=Microsoft; Publisher Customer ID=346fa229-7c19-44ef-85c6-29e00edf66cf; Unit Price=0.0; ERP=0.0; BenefitType=Charge; aks-managed-consolidated-additional-properties=92c34f68-4961-11f1-8cae-6277d8c8ca4f; aks-managed-creationSource=vmssclient-aks-systemeph-85241862-vmss; aks-managed-enable-imds-restriction=False; aks-managed-kubeletIdentityClientID=c5826f94-ec98-4f18-bd56-3490380ef971; aks-managed-operationID=585b1141-b235-488b-ae08-5da114d23dfb; aks-managed-orchestrator=Kubernetes:1.33.5; aks-managed-poolName=systemeph; aks-managed-resourceNameSuffix=40247467.0; aks-managed-ssh-access=LocalUser; compute.aks.billing=linux | V8: 16 | W8: 0
A9: May | B9: Microsoft CSP Azure Plan | C9: Divisi Inovasi | D9: divisiinovasi.onmicrosoft.com | E9: a4cdaa2e-caa7-440f-b849-928a3ceb7e31 | F9: AzureCSP_DivisiInovasi | G9: 1141685 | H9: VM RI | I9: Virtual Machines | J9: Virtual Machines RI | K9: Standard | L9: 46143 | M9: 46173 | N9: 0.133538 | O9: 1 Hour | P9: IDR | Q9: MC_RG-CANTALOUPE_CANTALOUPE_SOUTHEASTASIA | R9: aks-usereph2-16230473-vmss | S9: southeastasia | T9: { "Organization Name": "PT Nawa Darsana Teknologi", "Publisher": "Microsoft", "Publisher Customer ID": "346fa229-7c19-44ef-85c6-29e00edf66cf", "Unit Price": "0.0", "ERP": "0.0", "BenefitType": "Charge", "aks-managed-consolidated-additional-properties": "92c2fdef-4961-11f1-8cae-6277d8c8ca4f", "aks-managed-creationSource": "vmssclient-aks-usereph2-16230473-vmss", "aks-managed-enable-imds-restriction": "False", "aks-managed-kubeletIdentityClientID": "c5826f94-ec98-4f18-bd56-3490380ef971", "aks-managed-operationID": "585b1141-b235-488b-ae08-5da114d23dfb", "aks-managed-orchestrator": "Kubernetes:1.33.5", "aks-managed-poolName": "usereph2", "aks-managed-resourceNameSuffix": "40247467.0", "aks-managed-ssh-access": "LocalUser", "compute.aks.billing": "linux" } | U9: Organization Name=PT Nawa Darsana Teknologi; Publisher=Microsoft; Publisher Customer ID=346fa229-7c19-44ef-85c6-29e00edf66cf; Unit Price=0.0; ERP=0.0; BenefitType=Charge; aks-managed-consolidated-additional-properties=92c2fdef-4961-11f1-8cae-6277d8c8ca4f; aks-managed-creationSource=vmssclient-aks-usereph2-16230473-vmss; aks-managed-enable-imds-restriction=False; aks-managed-kubeletIdentityClientID=c5826f94-ec98-4f18-bd56-3490380ef971; aks-managed-operationID=585b1141-b235-488b-ae08-5da114d23dfb; aks-managed-orchestrator=Kubernetes:1.33.5; aks-managed-poolName=usereph2; aks-managed-resourceNameSuffix=40247467.0; aks-managed-ssh-access=LocalUser; compute.aks.billing=linux | V9: 16 | W9: 0
A10: May | B10: Microsoft CSP Azure Plan | C10: Divisi Inovasi | D10: divisiinovasi.onmicrosoft.com | E10: a4cdaa2e-caa7-440f-b849-928a3ceb7e31 | F10: AzureCSP_DivisiInovasi | G10: 1141685 | H10: VM RI | I10: Virtual Machines | J10: Virtual Machines RI | K10: Standard | L10: 46143 | M10: 46173 | N10: 37.816996 | O10: 1 Hour | P10: IDR | Q10: MC_RG-CANTALOUPE_CANTALOUPE_SOUTHEASTASIA | R10: aks-usereph2-16230473-vmss | S10: southeastasia | T10: { "Organization Name": "PT Nawa Darsana Teknologi", "Publisher": "Microsoft", "Publisher Customer ID": "346fa229-7c19-44ef-85c6-29e00edf66cf", "Unit Price": "0.0", "ERP": "0.0", "BenefitType": "Charge", "aks-managed-consolidated-additional-properties": "92c2fdef-4961-11f1-8cae-6277d8c8ca4f", "aks-managed-creationSource": "vmssclient-aks-usereph2-16230473-vmss", "aks-managed-enable-imds-restriction": "False", "aks-managed-kubeletIdentityClientID": "c5826f94-ec98-4f18-bd56-3490380ef971", "aks-managed-operationID": "585b1141-b235-488b-ae08-5da114d23dfb", "aks-managed-orchestrator": "Kubernetes:1.33.5", "aks-managed-poolName": "usereph2", "aks-managed-resourceNameSuffix": "40247467.0", "aks-managed-ssh-access": "LocalUser", "compute.aks.billing": "linux" } | U10: Organization Name=PT Nawa Darsana Teknologi; Publisher=Microsoft; Publisher Customer ID=346fa229-7c19-44ef-85c6-29e00edf66cf; Unit Price=0.0; ERP=0.0; BenefitType=Charge; aks-managed-consolidated-additional-properties=92c2fdef-4961-11f1-8cae-6277d8c8ca4f; aks-managed-creationSource=vmssclient-aks-usereph2-16230473-vmss; aks-managed-enable-imds-restriction=False; aks-managed-kubeletIdentityClientID=c5826f94-ec98-4f18-bd56-3490380ef971; aks-managed-operationID=585b1141-b235-488b-ae08-5da114d23dfb; aks-managed-orchestrator=Kubernetes:1.33.5; aks-managed-poolName=usereph2; aks-managed-resourceNameSuffix=40247467.0; aks-managed-ssh-access=LocalUser; compute.aks.billing=linux | V10: 16 | W10: 0
A11: May | B11: Microsoft CSP Azure Plan | C11: Divisi Inovasi | D11: divisiinovasi.onmicrosoft.com | E11: a4cdaa2e-caa7-440f-b849-928a3ceb7e31 | F11: AzureCSP_DivisiInovasi | G11: 1141685 | H11: Virtual Network Private Link | I11: Virtual Network | J11: Virtual Network Private Link | K11: Standard Private Endpoint | L11: 46143 | M11: 46173 | N11: 744 | O11: 1 Hour | P11: IDR | Q11: rg-cantaloupe | R11: aks-yellow-to-database-canggah | S11: southeastasia | T11: { "Organization Name": "PT Nawa Darsana Teknologi", "Publisher": "Microsoft", "Publisher Customer ID": "346fa229-7c19-44ef-85c6-29e00edf66cf", "Unit Price": "153.5248", "ERP": "129798.24", "BenefitType": "Charge", "San Marino": "San Marino" } | U11: Organization Name=PT Nawa Darsana Teknologi; Publisher=Microsoft; Publisher Customer ID=346fa229-7c19-44ef-85c6-29e00edf66cf; Unit Price=153.5248; ERP=129798.24; BenefitType=Charge; San Marino=San Marino | V11: 7 | W11: 129798.24
A12: May | B12: Microsoft CSP Azure Plan | C12: Divisi Inovasi | D12: divisiinovasi.onmicrosoft.com | E12: a4cdaa2e-caa7-440f-b849-928a3ceb7e31 | F12: AzureCSP_DivisiInovasi | G12: 1141685 | H12: Virtual Network Private Link | I12: Virtual Network | J12: Virtual Network Private Link | K12: Standard Private Endpoint | L12: 46143 | M12: 46173 | N12: 744 | O12: 1 Hour | P12: IDR | Q12: rg-cantaloupe | R12: aks-cantalopue-to-sweetpotatos | S12: southeastasia | T12: { "Organization Name": "PT Nawa Darsana Teknologi", "Publisher": "Microsoft", "Publisher Customer ID": "346fa229-7c19-44ef-85c6-29e00edf66cf", "Unit Price": "153.5248", "ERP": "129798.24", "BenefitType": "Charge", "CDN": "CDN" } | U12: Organization Name=PT Nawa Darsana Teknologi; Publisher=Microsoft; Publisher Customer ID=346fa229-7c19-44ef-85c6-29e00edf66cf; Unit Price=153.5248; ERP=129798.24; BenefitType=Charge; CDN=CDN | V12: 7 | W12: 129798.24
A13: May | B13: Microsoft CSP Azure Plan | C13: Divisi Inovasi | D13: divisiinovasi.onmicrosoft.com | E13: a4cdaa2e-caa7-440f-b849-928a3ceb7e31 | F13: AzureCSP_DivisiInovasi | G13: 1141685 | H13: VM RI | I13: Virtual Machines | J13: Virtual Machines RI | K13: Standard | L13: 46143 | M13: 46173 | N13: 4.600289 | O13: 1 Hour | P13: IDR | Q13: MC_RG-CANTALOUPE_CANTALOUPE_SOUTHEASTASIA | R13: aks-usereph2-16230473-vmss | S13: southeastasia | T13: { "Organization Name": "PT Nawa Darsana Teknologi", "Publisher": "Microsoft", "Publisher Customer ID": "346fa229-7c19-44ef-85c6-29e00edf66cf", "Unit Price": "0.0", "ERP": "0.0", "BenefitType": "Charge", "aks-managed-consolidated-additional-properties": "92c2fdef-4961-11f1-8cae-6277d8c8ca4f", "aks-managed-creationSource": "vmssclient-aks-usereph2-16230473-vmss", "aks-managed-enable-imds-restriction": "False", "aks-managed-kubeletIdentityClientID": "c5826f94-ec98-4f18-bd56-3490380ef971", "aks-managed-operationID": "585b1141-b235-488b-ae08-5da114d23dfb", "aks-managed-orchestrator": "Kubernetes:1.33.5", "aks-managed-poolName": "usereph2", "aks-managed-resourceNameSuffix": "40247467.0", "aks-managed-ssh-access": "LocalUser", "compute.aks.billing": "linux" } | U13: Organization Name=PT Nawa Darsana Teknologi; Publisher=Microsoft; Publisher Customer ID=346fa229-7c19-44ef-85c6-29e00edf66cf; Unit Price=0.0; ERP=0.0; BenefitType=Charge; aks-managed-consolidated-additional-properties=92c2fdef-4961-11f1-8cae-6277d8c8ca4f; aks-managed-creationSource=vmssclient-aks-usereph2-16230473-vmss; aks-managed-enable-imds-restriction=False; aks-managed-kubeletIdentityClientID=c5826f94-ec98-4f18-bd56-3490380ef971; aks-managed-operationID=585b1141-b235-488b-ae08-5da114d23dfb; aks-managed-orchestrator=Kubernetes:1.33.5; aks-managed-poolName=usereph2; aks-managed-resourceNameSuffix=40247467.0; aks-managed-ssh-access=LocalUser; compute.aks.billing=linux | V13: 16 | W13: 0
... A314: May | B314: Microsoft CSP Azure Plan | C314: Divisi Inovasi | D314: divisiinovasi.onmicrosoft.com | E314: a4cdaa2e-caa7-440f-b849-928a3ceb7e31 | F314: AzureCSP_DivisiInovasi | G314: 1141685 | H314: Blob Storage | I314: Storage | J314: Blob Storage | K314: Hot LRS Write Operations | L314: 46173 | M314: 46173 | N314: 1143.22 | O314: 10K | P314: IDR | Q314: rg-secops | R314: secopsdinov | S314: indonesiacentral | T314: { "Organization Name": "PT Nawa Darsana Teknologi", "Publisher": "Microsoft", "Publisher Customer ID": "346fa229-7c19-44ef-85c6-29e00edf66cf", "Unit Price": "108,92", "ERP": "11205276.021938255", "BenefitType": "Charge", "Environment": "Security-Operasional", "purpose": "Logs Google SecOps" } | U314: Organization Name=PT Nawa Darsana Teknologi; Publisher=Microsoft; Publisher Customer ID=346fa229-7c19-44ef-85c6-29e00edf66cf; Unit Price=108,92;BenefitType=Charge; Environment=Security-Operasional; purpose=Logs Google SecOps | V314: 7 | W314: 29016
A315: May | B315: Microsoft CSP Azure Plan | C315: Divisi Inovasi | D315: divisiinovasi.onmicrosoft.com | E315: a4cdaa2e-caa7-440f-b849-928a3ceb7e31 | F315: AzureCSP_DivisiInovasi | G315: 1141685 | H315: SQL Database Single/ElasticPool General Purpose - Compute Gen5 | I315: =IF(LEFT(K315,9)="Standard_","Reserved Instance Virtual Machine",IF(ISNUMBER(SEARCH("SQL Database Single/ElasticPool General Purpose - Compute Gen5",K315)),"Reserved Instance SQL Database",IF(ISNUMBER(SEARCH("SQL Database SingleDB/Elastic Pool Hyperscale - Compute Gen5",K315)),"Reserved Instance Hyperscale Serverless",IF(ISNUMBER(SEARCH("Azure Database for PostgreSQL Flexible Server General Purpose Ddsv4 Series Compute",K315)),"Reserved Instance PostgreSQL",IF(ISNUMBER(SEARCH("Azure Redis Cache Premium",K315)),"Reserved Instance Redis","Reserved Instance"))))) -> Reserved Instance SQL Database | J315: SQL Database Single/ElasticPool General Purpose - Compute Gen5 | K315: =H315 -> SQL Database Single/ElasticPool General Purpose - Compute Gen5 | L315: 3 Years | M315: 3 Years | N315: =U315 -> 8 | O315: Reserved Instance | P315: IDR | Q315: Reserved Instance | R315: =IF(LEFT(K315,9)="Standard_","Virtual Machine",IF(ISNUMBER(SEARCH("SQL Database Single/ElasticPool General Purpose - Compute Gen5",K315)),"SQL Database",IF(ISNUMBER(SEARCH("SQL Database SingleDB/Elastic Pool Hyperscale - Compute Gen5",K315)),"Hyperscale Serverless",IF(ISNUMBER(SEARCH("Azure Database for PostgreSQL Flexible Server General Purpose Ddsv4 Series Compute",K315)),"PostgreSQL",IF(ISNUMBER(SEARCH("Azure Redis Cache Premium",K315)),"Redis",K315))))) -> SQL Database | S315: southeastasia | T315: Reserved Instance | U315: 8 | V315: 1001385 | W315: =U315*V315 -> 8011080 | X315: CDN
A316: May | B316: Microsoft CSP Azure Plan | C316: Divisi Inovasi | D316: divisiinovasi.onmicrosoft.com | E316: a4cdaa2e-caa7-440f-b849-928a3ceb7e33 | F316: AzureCSP_DivisiInovasi | G316: 1141685 | H316: Standard_D2s_v3 | I316: =IF(LEFT(K316,9)="Standard_","Reserved Instance Virtual Machine",IF(ISNUMBER(SEARCH("SQL Database Single/ElasticPool General Purpose - Compute Gen5",K316)),"Reserved Instance SQL Database",IF(ISNUMBER(SEARCH("SQL Database SingleDB/Elastic Pool Hyperscale - Compute Gen5",K316)),"Reserved Instance Hyperscale Serverless",IF(ISNUMBER(SEARCH("Azure Database for PostgreSQL Flexible Server General Purpose Ddsv4 Series Compute",K316)),"Reserved Instance PostgreSQL",IF(ISNUMBER(SEARCH("Azure Redis Cache Premium",K316)),"Reserved Instance Redis","Reserved Instance"))))) -> Reserved Instance Virtual Machine | J316: Standard_D2s_v3 | K316: =H316 -> Standard_D2s_v3 | L316: 3 Years | M316: 3 Years | N316: =U316 -> 3 | O316: Reserved Instance | P316: IDR | Q316: Reserved Instance | R316: =IF(LEFT(K316,9)="Standard_","Virtual Machine",IF(ISNUMBER(SEARCH("SQL Database Single/ElasticPool General Purpose - Compute Gen5",K316)),"SQL Database",IF(ISNUMBER(SEARCH("SQL Database SingleDB/Elastic Pool Hyperscale - Compute Gen5",K316)),"Hyperscale Serverless",IF(ISNUMBER(SEARCH("Azure Database for PostgreSQL Flexible Server General Purpose Ddsv4 Series Compute",K316)),"PostgreSQL",IF(ISNUMBER(SEARCH("Azure Redis Cache Premium",K316)),"Redis",K316))))) -> Virtual Machine | S316: southeastasia | T316: Reserved Instance | U316: 3 | V316: 565656.3 | W316: =U316*V316 -> 1696968.9 | X316: CDN
A317: May | B317: Microsoft CSP Azure Plan | C317: Divisi Inovasi | D317: divisiinovasi.onmicrosoft.com | E317: a4cdaa2e-caa7-440f-b849-928a3ceb7e32 | F317: AzureCSP_DivisiInovasi | G317: 1141685 | H317: Standard_D4s_v3 | I317: =IF(LEFT(K317,9)="Standard_","Reserved Instance Virtual Machine",IF(ISNUMBER(SEARCH("SQL Database Single/ElasticPool General Purpose - Compute Gen5",K317)),"Reserved Instance SQL Database",IF(ISNUMBER(SEARCH("SQL Database SingleDB/Elastic Pool Hyperscale - Compute Gen5",K317)),"Reserved Instance Hyperscale Serverless",IF(ISNUMBER(SEARCH("Azure Database for PostgreSQL Flexible Server General Purpose Ddsv4 Series Compute",K317)),"Reserved Instance PostgreSQL",IF(ISNUMBER(SEARCH("Azure Redis Cache Premium",K317)),"Reserved Instance Redis","Reserved Instance"))))) -> Reserved Instance Virtual Machine | J317: Standard_D4s_v3 | K317: =H317 -> Standard_D4s_v3 | L317: 3 Years | M317: 3 Years | N317: =U317 -> 3 | O317: Reserved Instance | P317: IDR | Q317: Reserved Instance | R317: =IF(LEFT(K317,9)="Standard_","Virtual Machine",IF(ISNUMBER(SEARCH("SQL Database Single/ElasticPool General Purpose - Compute Gen5",K317)),"SQL Database",IF(ISNUMBER(SEARCH("SQL Database SingleDB/Elastic Pool Hyperscale - Compute Gen5",K317)),"Hyperscale Serverless",IF(ISNUMBER(SEARCH("Azure Database for PostgreSQL Flexible Server General Purpose Ddsv4 Series Compute",K317)),"PostgreSQL",IF(ISNUMBER(SEARCH("Azure Redis Cache Premium",K317)),"Redis",K317))))) -> Virtual Machine | S317: southeastasia | T317: Reserved Instance | U317: 3 | V317: 1131817.5 | W317: =U317*V317 -> 3395452.5 | X317: CDN

Sheet Detail_HPM
A1: Period | B1: Agreement Name | C1: Company Name | D1: Tenant Primary Domain | E1: Publisher Subscription ID | F1: Publisher Subscription Name | G1: Product ID | H1: Product Name | I1: Category | J1: Subcategory | K1: Meter Name | L1: Usage Start Date | M1: Usage End Date | N1: Quantity | O1: Unit | P1: Currency | Q1: Resource Group Name | R1: Resource Name | S1: Location | T1: Tags_JSON | U1: Tags_KeyValue | V1: Tags_Count | W1: Total
A2: May | B2: Microsoft CSP Azure Plan | C2: Divisi Inovasi | D2: divisiinovasi.onmicrosoft.com | E2: a4cdaa2e-caa7-440f-b849-928a3ceb7e31 | F2: AzureCSP_DivisiInovasi | G2: 1141685 | H2: VM RI | I2: Virtual Machines | J2: Virtual Machines RI | K2: Standard | L2: 46143 | M2: 46173 | N2: 12.716642 | O2: 1 Hour | P2: IDR | Q2: MC_RG-HPM_HAMALOMENA_SOUTHEASTASIA | R2: aks-usereph2-29555450-vmss | S2: southeastasia | T2: { "Organization Name": "PT Nawa Darsana Teknologi", "Publisher": "Microsoft", "Publisher Customer ID": "346fa229-7c19-44ef-85c6-29e00edf66cf", "Unit Price": "0.0", "ERP": "0.0", "BenefitType": "Charge", "aks-managed-consolidated-additional-properties": "eb8f3d2d-4967-11f1-ad6b-a26c3881ebea", "aks-managed-creationSource": "vmssclient-aks-usereph2-29555450-vmss", "aks-managed-enable-imds-restriction": "False", "aks-managed-kubeletIdentityClientID": "7a362009-e35e-4c70-b3ae-c3b865d60358", "aks-managed-operationID": "628c9d70-3cdf-4197-af26-cb0e6c529e6b", "aks-managed-orchestrator": "Kubernetes:1.33.5", "aks-managed-poolName": "usereph2", "aks-managed-resourceNameSuffix": "41829248.0", "aks-managed-ssh-access": "LocalUser", "compute.aks.billing": "linux" } | U2: Organization Name=PT Nawa Darsana Teknologi; Publisher=Microsoft; Publisher Customer ID=346fa229-7c19-44ef-85c6-29e00edf66cf; Unit Price=0.0; ERP=0.0; BenefitType=Charge; aks-managed-consolidated-additional-properties=eb8f3d2d-4967-11f1-ad6b-a26c3881ebea; aks-managed-creationSource=vmssclient-aks-usereph2-29555450-vmss; aks-managed-enable-imds-restriction=False; aks-managed-kubeletIdentityClientID=7a362009-e35e-4c70-b3ae-c3b865d60358; aks-managed-operationID=628c9d70-3cdf-4197-af26-cb0e6c529e6b; aks-managed-orchestrator=Kubernetes:1.33.5; aks-managed-poolName=usereph2; aks-managed-resourceNameSuffix=41829248.0; aks-managed-ssh-access=LocalUser; compute.aks.billing=linux | V2: 16 | W2: 0
A3: May | B3: Microsoft CSP Azure Plan | C3: Divisi Inovasi | D3: divisiinovasi.onmicrosoft.com | E3: a4cdaa2e-caa7-440f-b849-928a3ceb7e31 | F3: AzureCSP_DivisiInovasi | G3: 1141685 | H3: VM RI | I3: Virtual Machines | J3: Virtual Machines RI | K3: Standard | L3: 46143 | M3: 46173 | N3: 152.53175 | O3: 1 Hour | P3: IDR | Q3: MC_RG-HPM_HAMALOMENA_SOUTHEASTASIA | R3: aks-usereph2-29555450-vmss | S3: southeastasia | T3: { "Organization Name": "PT Nawa Darsana Teknologi", "Publisher": "Microsoft", "Publisher Customer ID": "346fa229-7c19-44ef-85c6-29e00edf66cf", "Unit Price": "0.0", "ERP": "0.0", "BenefitType": "Charge", "aks-managed-consolidated-additional-properties": "eb8f3d2d-4967-11f1-ad6b-a26c3881ebea", "aks-managed-creationSource": "vmssclient-aks-usereph2-29555450-vmss", "aks-managed-enable-imds-restriction": "False", "aks-managed-kubeletIdentityClientID": "7a362009-e35e-4c70-b3ae-c3b865d60358", "aks-managed-operationID": "628c9d70-3cdf-4197-af26-cb0e6c529e6b", "aks-managed-orchestrator": "Kubernetes:1.33.5", "aks-managed-poolName": "usereph2", "aks-managed-resourceNameSuffix": "41829248.0", "aks-managed-ssh-access": "LocalUser", "compute.aks.billing": "linux" } | U3: Organization Name=PT Nawa Darsana Teknologi; Publisher=Microsoft; Publisher Customer ID=346fa229-7c19-44ef-85c6-29e00edf66cf; Unit Price=0.0; ERP=0.0; BenefitType=Charge; aks-managed-consolidated-additional-properties=eb8f3d2d-4967-11f1-ad6b-a26c3881ebea; aks-managed-creationSource=vmssclient-aks-usereph2-29555450-vmss; aks-managed-enable-imds-restriction=False; aks-managed-kubeletIdentityClientID=7a362009-e35e-4c70-b3ae-c3b865d60358; aks-managed-operationID=628c9d70-3cdf-4197-af26-cb0e6c529e6b; aks-managed-orchestrator=Kubernetes:1.33.5; aks-managed-poolName=usereph2; aks-managed-resourceNameSuffix=41829248.0; aks-managed-ssh-access=LocalUser; compute.aks.billing=linux | V3: 16 | W3: 0
A4: May | B4: Microsoft CSP Azure Plan | C4: Divisi Inovasi | D4: divisiinovasi.onmicrosoft.com | E4: a4cdaa2e-caa7-440f-b849-928a3ceb7e31 | F4: AzureCSP_DivisiInovasi | G4: 1141685 | H4: VM RI | I4: Virtual Machines | J4: Virtual Machines RI | K4: Standard | L4: 46143 | M4: 46173 | N4: 0.983352 | O4: 1 Hour | P4: IDR | Q4: MC_RG-HPM_HAMALOMENA_SOUTHEASTASIA | R4: aks-usereph2-29555450-vmss | S4: southeastasia | T4: { "Organization Name": "PT Nawa Darsana Teknologi", "Publisher": "Microsoft", "Publisher Customer ID": "346fa229-7c19-44ef-85c6-29e00edf66cf", "Unit Price": "0.0", "ERP": "0.0", "BenefitType": "Charge", "aks-managed-consolidated-additional-properties": "eb8f3d2d-4967-11f1-ad6b-a26c3881ebea", "aks-managed-creationSource": "vmssclient-aks-usereph2-29555450-vmss", "aks-managed-enable-imds-restriction": "False", "aks-managed-kubeletIdentityClientID": "7a362009-e35e-4c70-b3ae-c3b865d60358", "aks-managed-operationID": "628c9d70-3cdf-4197-af26-cb0e6c529e6b", "aks-managed-orchestrator": "Kubernetes:1.33.5", "aks-managed-poolName": "usereph2", "aks-managed-resourceNameSuffix": "41829248.0", "aks-managed-ssh-access": "LocalUser", "compute.aks.billing": "linux" } | U4: Organization Name=PT Nawa Darsana Teknologi; Publisher=Microsoft; Publisher Customer ID=346fa229-7c19-44ef-85c6-29e00edf66cf; Unit Price=0.0; ERP=0.0; BenefitType=Charge; aks-managed-consolidated-additional-properties=eb8f3d2d-4967-11f1-ad6b-a26c3881ebea; aks-managed-creationSource=vmssclient-aks-usereph2-29555450-vmss; aks-managed-enable-imds-restriction=False; aks-managed-kubeletIdentityClientID=7a362009-e35e-4c70-b3ae-c3b865d60358; aks-managed-operationID=628c9d70-3cdf-4197-af26-cb0e6c529e6b; aks-managed-orchestrator=Kubernetes:1.33.5; aks-managed-poolName=usereph2; aks-managed-resourceNameSuffix=41829248.0; aks-managed-ssh-access=LocalUser; compute.aks.billing=linux | V4: 16 | W4: 0
A5: May | B5: Microsoft CSP Azure Plan | C5: Divisi Inovasi | D5: divisiinovasi.onmicrosoft.com | E5: a4cdaa2e-caa7-440f-b849-928a3ceb7e31 | F5: AzureCSP_DivisiInovasi | G5: 1141685 | H5: VM RI | I5: Virtual Machines | J5: Virtual Machines RI | K5: Standard | L5: 46143 | M5: 46173 | N5: 0.383539 | O5: 1 Hour | P5: IDR | Q5: MC_RG-HPM_HAMALOMENA_SOUTHEASTASIA | R5: aks-usereph2-29555450-vmss | S5: southeastasia | T5: { "Organization Name": "PT Nawa Darsana Teknologi", "Publisher": "Microsoft", "Publisher Customer ID": "346fa229-7c19-44ef-85c6-29e00edf66cf", "Unit Price": "0.0", "ERP": "0.0", "BenefitType": "Charge", "aks-managed-consolidated-additional-properties": "e4642263-ea08-11f0-bf79-fe421b86da3b", "aks-managed-creationSource": "vmssclient-aks-usereph2-29555450-vmss", "aks-managed-enable-imds-restriction": "False", "aks-managed-kubeletIdentityClientID": "7a362009-e35e-4c70-b3ae-c3b865d60358", "aks-managed-operationID": "04dad870-bcfc-4b75-bd10-975af82078e0", "aks-managed-orchestrator": "Kubernetes:1.33.5", "aks-managed-poolName": "usereph2", "aks-managed-resourceNameSuffix": "41829248.0", "aks-managed-ssh-access": "LocalUser" } | U5: Organization Name=PT Nawa Darsana Teknologi; Publisher=Microsoft; Publisher Customer ID=346fa229-7c19-44ef-85c6-29e00edf66cf; Unit Price=0.0; ERP=0.0; BenefitType=Charge; aks-managed-consolidated-additional-properties=e4642263-ea08-11f0-bf79-fe421b86da3b; aks-managed-creationSource=vmssclient-aks-usereph2-29555450-vmss; aks-managed-enable-imds-restriction=False; aks-managed-kubeletIdentityClientID=7a362009-e35e-4c70-b3ae-c3b865d60358; aks-managed-operationID=04dad870-bcfc-4b75-bd10-975af82078e0; aks-managed-orchestrator=Kubernetes:1.33.5; aks-managed-poolName=usereph2; aks-managed-resourceNameSuffix=41829248.0; aks-managed-ssh-access=LocalUser | V5: 15 | W5: 0
A6: May | B6: Microsoft CSP Azure Plan | C6: Divisi Inovasi | D6: divisiinovasi.onmicrosoft.com | E6: a4cdaa2e-caa7-440f-b849-928a3ceb7e31 | F6: AzureCSP_DivisiInovasi | G6: 1141685 | H6: Load Balancer | I6: Load Balancer | J6: Load Balancer | K6: Standard Data Processed | L6: 46143 | M6: 46173 | N6: 2799.5886 | O6: 1 GB | P6: IDR | Q6: mc_rg-hpm_hamalomena_southeastasia | R6: kubernetes | S6: southeastasia | T6: { "Organization Name": "PT Nawa Darsana Teknologi", "Publisher": "Microsoft", "Publisher Customer ID": "346fa229-7c19-44ef-85c6-29e00edf66cf", "Unit Price": "76.7624", "ERP": "244208.117860993", "BenefitType": "Charge", "aks-managed-cluster-name": "Hamalomena", "aks-managed-cluster-rg": "rg-hpm", "Environment": "Production", "Hayati": "CE", "MD": "Hayati", "Product": "CE" } | U6: Organization Name=PT Nawa Darsana Teknologi; Publisher=Microsoft; Publisher Customer ID=346fa229-7c19-44ef-85c6-29e00edf66cf; Unit Price=76.7624; ERP=244208.117860993; BenefitType=Charge; aks-managed-cluster-name=Hamalomena; aks-managed-cluster-rg=rg-hpm; Environment=Production; Hayati=CE; MD=Hayati; Product=CE | V6: 12 | W6: 244208.11
A7: May | B7: Microsoft CSP Azure Plan | C7: Divisi Inovasi | D7: divisiinovasi.onmicrosoft.com | E7: a4cdaa2e-caa7-440f-b849-928a3ceb7e31 | F7: AzureCSP_DivisiInovasi | G7: 1141685 | H7: Bd Inter-Rgn | I7: Bandwidth | J7: Bandwidth Inter-Region | K7: Intra Continent Data Transfer Out | L7: 46143 | M7: 46173 | N7: 0.14690831 | O7: 1 GB | P7: IDR | Q7: mc_rg-hpm_hamalomena_southeastasia | R7: aks-usereph2-29555450-vmss | S7: southeastasia | T7: { "Organization Name": "PT Nawa Darsana Teknologi", "Publisher": "Microsoft", "Publisher Customer ID": "346fa229-7c19-44ef-85c6-29e00edf66cf", "Unit Price": "1228.1983999968", "ERP": "205.0369901008", "BenefitType": "Charge", "aks-managed-consolidated-additional-properties": "e4642263-ea08-11f0-bf79-fe421b86da3b", "aks-managed-creationSource": "vmssclient-aks-usereph2-29555450-vmss", "aks-managed-enable-imds-restriction": "False", "aks-managed-kubeletIdentityClientID": "7a362009-e35e-4c70-b3ae-c3b865d60358", "aks-managed-operationID": "04dad870-bcfc-4b75-bd10-975af82078e0", "aks-managed-orchestrator": "Kubernetes:1.33.5", "aks-managed-poolName": "usereph2", "aks-managed-resourceNameSuffix": "41829248.0", "aks-managed-ssh-access": "LocalUser" } | U7: Organization Name=PT Nawa Darsana Teknologi; Publisher=Microsoft; Publisher Customer ID=346fa229-7c19-44ef-85c6-29e00edf66cf; Unit Price=1228.1983999968; ERP=205.0369901008; BenefitType=Charge; aks-managed-consolidated-additional-properties=e4642263-ea08-11f0-bf79-fe421b86da3b; aks-managed-creationSource=vmssclient-aks-usereph2-29555450-vmss; aks-managed-enable-imds-restriction=False; aks-managed-kubeletIdentityClientID=7a362009-e35e-4c70-b3ae-c3b865d60358; aks-managed-operationID=04dad870-bcfc-4b75-bd10-975af82078e0; aks-managed-orchestrator=Kubernetes:1.33.5; aks-managed-poolName=usereph2; aks-managed-resourceNameSuffix=41829248.0; aks-managed-ssh-access=LocalUser | V7: 15 | W7: 205.03255
A8: May | B8: Microsoft CSP Azure Plan | C8: Divisi Inovasi | D8: divisiinovasi.onmicrosoft.com | E8: a4cdaa2e-caa7-440f-b849-928a3ceb7e31 | F8: AzureCSP_DivisiInovasi | G8: 1141685 | H8: Bd Inter-Rgn | I8: Bandwidth | J8: Bandwidth Inter-Region | K8: Intra Continent Data Transfer Out | L8: 46143 | M8: 46173 | N8: 0.15740453 | O8: 1 GB | P8: IDR | Q8: mc_rg-hpm_hamalomena_southeastasia | R8: aks-usereph2-29555450-vmss | S8: southeastasia | T8: { "Organization Name": "PT Nawa Darsana Teknologi", "Publisher": "Microsoft", "Publisher Customer ID": "346fa229-7c19-44ef-85c6-29e00edf66cf", "Unit Price": "1228.1983999974", "ERP": "219.6863579196", "BenefitType": "Charge", "aks-managed-consolidated-additional-properties": "e4642263-ea08-11f0-bf79-fe421b86da3b", "aks-managed-creationSource": "vmssclient-aks-usereph2-29555450-vmss", "aks-managed-enable-imds-restriction": "False", "aks-managed-kubeletIdentityClientID": "7a362009-e35e-4c70-b3ae-c3b865d60358", "aks-managed-operationID": "04dad870-bcfc-4b75-bd10-975af82078e0", "aks-managed-orchestrator": "Kubernetes:1.33.5", "aks-managed-poolName": "usereph2", "aks-managed-resourceNameSuffix": "41829248.0", "aks-managed-ssh-access": "LocalUser" } | U8: Organization Name=PT Nawa Darsana Teknologi; Publisher=Microsoft; Publisher Customer ID=346fa229-7c19-44ef-85c6-29e00edf66cf; Unit Price=1228.1983999974; ERP=219.6863579196; BenefitType=Charge; aks-managed-consolidated-additional-properties=e4642263-ea08-11f0-bf79-fe421b86da3b; aks-managed-creationSource=vmssclient-aks-usereph2-29555450-vmss; aks-managed-enable-imds-restriction=False; aks-managed-kubeletIdentityClientID=7a362009-e35e-4c70-b3ae-c3b865d60358; aks-managed-operationID=04dad870-bcfc-4b75-bd10-975af82078e0; aks-managed-orchestrator=Kubernetes:1.33.5; aks-managed-poolName=usereph2; aks-managed-resourceNameSuffix=41829248.0; aks-managed-ssh-access=LocalUser | V8: 15 | W8: 219.684
A9: May | B9: Microsoft CSP Azure Plan | C9: Divisi Inovasi | D9: divisiinovasi.onmicrosoft.com | E9: a4cdaa2e-caa7-440f-b849-928a3ceb7e31 | F9: AzureCSP_DivisiInovasi | G9: 1141685 | H9: Bd Inter-Rgn | I9: Bandwidth | J9: Bandwidth Inter-Region | K9: Intra Continent Data Transfer Out | L9: 46143 | M9: 46173 | N9: 3.353e-07 | O9: 1 GB | P9: IDR | Q9: mc_rg-hpm_hamalomena_southeastasia | R9: aks-usereph2-29555450-vmss | S9: southeastasia | T9: { "Organization Name": "PT Nawa Darsana Teknologi", "Publisher": "Microsoft", "Publisher Customer ID": "346fa229-7c19-44ef-85c6-29e00edf66cf", "Unit Price": "1228.198043016", "ERP": "0.0004675528", "BenefitType": "Charge", "aks-managed-consolidated-additional-properties": "eb8f3d2d-4967-11f1-ad6b-a26c3881ebea", "aks-managed-creationSource": "vmssclient-aks-usereph2-29555450-vmss", "aks-managed-enable-imds-restriction": "False", "aks-managed-kubeletIdentityClientID": "7a362009-e35e-4c70-b3ae-c3b865d60358", "aks-managed-operationID": "628c9d70-3cdf-4197-af26-cb0e6c529e6b", "aks-managed-orchestrator": "Kubernetes:1.33.5", "aks-managed-poolName": "usereph2", "aks-managed-resourceNameSuffix": "41829248.0", "aks-managed-ssh-access": "LocalUser", "compute.aks.billing": "linux" } | U9: Organization Name=PT Nawa Darsana Teknologi; Publisher=Microsoft; Publisher Customer ID=346fa229-7c19-44ef-85c6-29e00edf66cf; Unit Price=1228.198043016; ERP=0.0004675528; BenefitType=Charge; aks-managed-consolidated-additional-properties=eb8f3d2d-4967-11f1-ad6b-a26c3881ebea; aks-managed-creationSource=vmssclient-aks-usereph2-29555450-vmss; aks-managed-enable-imds-restriction=False; aks-managed-kubeletIdentityClientID=7a362009-e35e-4c70-b3ae-c3b865d60358; aks-managed-operationID=628c9d70-3cdf-4197-af26-cb0e6c529e6b; aks-managed-orchestrator=Kubernetes:1.33.5; aks-managed-poolName=usereph2; aks-managed-resourceNameSuffix=41829248.0; aks-managed-ssh-access=LocalUser; compute.aks.billing=linux | V9: 16 | W9: 0.0004117855
A10: May | B10: Microsoft CSP Azure Plan | C10: Divisi Inovasi | D10: divisiinovasi.onmicrosoft.com | E10: a4cdaa2e-caa7-440f-b849-928a3ceb7e31 | F10: AzureCSP_DivisiInovasi | G10: 1141685 | H10: VM RI | I10: Virtual Machines | J10: Virtual Machines RI | K10: Standard | L10: 46143 | M10: 46173 | N10: 37.599523 | O10: 1 Hour | P10: IDR | Q10: MC_RG-HPM_HAMALOMENA_SOUTHEASTASIA | R10: aks-usereph2-29555450-vmss | S10: southeastasia | T10: { "Organization Name": "PT Nawa Darsana Teknologi", "Publisher": "Microsoft", "Publisher Customer ID": "346fa229-7c19-44ef-85c6-29e00edf66cf", "Unit Price": "0.0", "ERP": "0.0", "BenefitType": "Charge", "aks-managed-consolidated-additional-properties": "eb8f3d2d-4967-11f1-ad6b-a26c3881ebea", "aks-managed-creationSource": "vmssclient-aks-usereph2-29555450-vmss", "aks-managed-enable-imds-restriction": "False", "aks-managed-kubeletIdentityClientID": "7a362009-e35e-4c70-b3ae-c3b865d60358", "aks-managed-operationID": "628c9d70-3cdf-4197-af26-cb0e6c529e6b", "aks-managed-orchestrator": "Kubernetes:1.33.5", "aks-managed-poolName": "usereph2", "aks-managed-resourceNameSuffix": "41829248.0", "aks-managed-ssh-access": "LocalUser", "compute.aks.billing": "linux" } | U10: Organization Name=PT Nawa Darsana Teknologi; Publisher=Microsoft; Publisher Customer ID=346fa229-7c19-44ef-85c6-29e00edf66cf; Unit Price=0.0; ERP=0.0; BenefitType=Charge; aks-managed-consolidated-additional-properties=eb8f3d2d-4967-11f1-ad6b-a26c3881ebea; aks-managed-creationSource=vmssclient-aks-usereph2-29555450-vmss; aks-managed-enable-imds-restriction=False; aks-managed-kubeletIdentityClientID=7a362009-e35e-4c70-b3ae-c3b865d60358; aks-managed-operationID=628c9d70-3cdf-4197-af26-cb0e6c529e6b; aks-managed-orchestrator=Kubernetes:1.33.5; aks-managed-poolName=usereph2; aks-managed-resourceNameSuffix=41829248.0; aks-managed-ssh-access=LocalUser; compute.aks.billing=linux | V10: 16 | W10: 0
A11: May | B11: Microsoft CSP Azure Plan | C11: Divisi Inovasi | D11: divisiinovasi.onmicrosoft.com | E11: a4cdaa2e-caa7-440f-b849-928a3ceb7e31 | F11: AzureCSP_DivisiInovasi | G11: 1141685 | H11: SQL DB Single/Elastic Pool GP-SQL Licen | I11: SQL Database | J11: SQL Database Single/Elastic Pool General Purpose - SQL License | K11: vCore | L11: 46143 | M11: 46173 | N11: 434 | O11: 1 Hour | P11: IDR | Q11: RG-HPM | R11: haruman | S11: southeastasia | T11: { "Organization Name": "PT Nawa Darsana Teknologi", "Publisher": "Microsoft", "Publisher Customer ID": "346fa229-7c19-44ef-85c6-29e00edf66cf", "Unit Price": "1534.72601568", "ERP": "756898.966824", "BenefitType": "Charge" } | U11: Organization Name=PT Nawa Darsana Teknologi; Publisher=Microsoft; Publisher Customer ID=346fa229-7c19-44ef-85c6-29e00edf66cf; Unit Price=1534.72601568; ERP=756898.966824; BenefitType=Charge | V11: 6 | W11: 756898.97
A12: May | B12: Microsoft CSP Azure Plan | C12: Divisi Inovasi | D12: divisiinovasi.onmicrosoft.com | E12: a4cdaa2e-caa7-440f-b849-928a3ceb7e31 | F12: AzureCSP_DivisiInovasi | G12: 1141685 | H12: Virtual Network Private Link | I12: Virtual Network | J12: Virtual Network Private Link | K12: Standard Data Processed - Ingress | L12: 46143 | M12: 46173 | N12: 0.58083037 | O12: 1 GB | P12: IDR | Q12: mc_rg-hpm_hamalomena_southeastasia | R12: aks-systemeph-26423959-vmss | S12: southeastasia | T12: { "Organization Name": "PT Nawa Darsana Teknologi", "Publisher": "Microsoft", "Publisher Customer ID": "346fa229-7c19-44ef-85c6-29e00edf66cf", "Unit Price": "153.524799999", "ERP": "101.3316646056", "BenefitType": "Charge", "aks-managed-consolidated-additional-properties": "e4642eba-ea08-11f0-bf79-fe421b86da3b", "aks-managed-creationSource": "vmssclient-aks-systemeph-26423959-vmss", "aks-managed-enable-imds-restriction": "False", "aks-managed-kubeletIdentityClientID": "7a362009-e35e-4c70-b3ae-c3b865d60358", "aks-managed-operationID": "04dad870-bcfc-4b75-bd10-975af82078e0", "aks-managed-orchestrator": "Kubernetes:1.33.5", "aks-managed-poolName": "systemeph", "aks-managed-resourceNameSuffix": "41829248.0", "aks-managed-ssh-access": "LocalUser" } | U12: Organization Name=PT Nawa Darsana Teknologi; Publisher=Microsoft; Publisher Customer ID=346fa229-7c19-44ef-85c6-29e00edf66cf; Unit Price=153.524799999; ERP=101.3316646056; BenefitType=Charge; aks-managed-consolidated-additional-properties=e4642eba-ea08-11f0-bf79-fe421b86da3b; aks-managed-creationSource=vmssclient-aks-systemeph-26423959-vmss; aks-managed-enable-imds-restriction=False; aks-managed-kubeletIdentityClientID=7a362009-e35e-4c70-b3ae-c3b865d60358; aks-managed-operationID=04dad870-bcfc-4b75-bd10-975af82078e0; aks-managed-orchestrator=Kubernetes:1.33.5; aks-managed-poolName=systemeph; aks-managed-resourceNameSuffix=41829248.0; aks-managed-ssh-access=LocalUser | V12: 15 | W12: 101.33187
A13: May | B13: Microsoft CSP Azure Plan | C13: Divisi Inovasi | D13: divisiinovasi.onmicrosoft.com | E13: a4cdaa2e-caa7-440f-b849-928a3ceb7e31 | F13: AzureCSP_DivisiInovasi | G13: 1141685 | H13: Virtual Network Private Link | I13: Virtual Network | J13: Virtual Network Private Link | K13: Standard Data Processed - Egress | L13: 46143 | M13: 46173 | N13: 0.0030481033 | O13: 1 GB | P13: IDR | Q13: mc_rg-hpm_hamalomena_southeastasia | R13: aks-systemeph-26423959-vmss | S13: southeastasia | T13: { "Organization Name": "PT Nawa Darsana Teknologi", "Publisher": "Microsoft", "Publisher Customer ID": "346fa229-7c19-44ef-85c6-29e00edf66cf", "Unit Price": "153.5247999817", "ERP": "0.531771526", "BenefitType": "Charge", "aks-managed-consolidated-additional-properties": "eb8fb298-4967-11f1-ad6b-a26c3881ebea", "aks-managed-creationSource": "vmssclient-aks-systemeph-26423959-vmss", "aks-managed-enable-imds-restriction": "False", "aks-managed-kubeletIdentityClientID": "7a362009-e35e-4c70-b3ae-c3b865d60358", "aks-managed-operationID": "628c9d70-3cdf-4197-af26-cb0e6c529e6b", "aks-managed-orchestrator": "Kubernetes:1.33.5", "aks-managed-poolName": "systemeph", "aks-managed-resourceNameSuffix": "41829248.0", "aks-managed-ssh-access": "LocalUser", "compute.aks.billing": "linux" } | U13: Organization Name=PT Nawa Darsana Teknologi; Publisher=Microsoft; Publisher Customer ID=346fa229-7c19-44ef-85c6-29e00edf66cf; Unit Price=153.5247999817; ERP=0.531771526; BenefitType=Charge; aks-managed-consolidated-additional-properties=eb8fb298-4967-11f1-ad6b-a26c3881ebea; aks-managed-creationSource=vmssclient-aks-systemeph-26423959-vmss; aks-managed-enable-imds-restriction=False; aks-managed-kubeletIdentityClientID=7a362009-e35e-4c70-b3ae-c3b865d60358; aks-managed-operationID=628c9d70-3cdf-4197-af26-cb0e6c529e6b; aks-managed-orchestrator=Kubernetes:1.33.5; aks-managed-poolName=systemeph; aks-managed-resourceNameSuffix=41829248.0; aks-managed-ssh-access=LocalUser; compute.aks.billing=linux | V13: 16 | W13: 0.52795945
... A320: May | B320: Microsoft CSP Azure Plan | C320: Divisi Inovasi | D320: divisiinovasi.onmicrosoft.com | E320: a4cdaa2e-caa7-440f-b849-928a3ceb7e31 | F320: AzureCSP_DivisiInovasi | G320: 1141685 | H320: Blob Storage | I320: Storage | J320: Blob Storage | K320: Hot LRS Write Operations | L320: 46173 | M320: 46173 | N320: 1143.22 | O320: 10K | P320: IDR | Q320: rg-secops | R320: secopsdinov | S320: indonesiacentral | T320: { "Organization Name": "PT Nawa Darsana Teknologi", "Publisher": "Microsoft", "Publisher Customer ID": "346fa229-7c19-44ef-85c6-29e00edf66cf", "Unit Price": "108,92", "ERP": "11205276.021938255", "BenefitType": "Charge", "Environment": "Security-Operasional", "purpose": "Logs Google SecOps" } | U320: Organization Name=PT Nawa Darsana Teknologi; Publisher=Microsoft; Publisher Customer ID=346fa229-7c19-44ef-85c6-29e00edf66cf; Unit Price=108,92;BenefitType=Charge; Environment=Security-Operasional; purpose=Logs Google SecOps | V320: 7 | W320: 29016
A321: May | B321: Microsoft CSP Azure Plan | C321: Divisi Inovasi | D321: divisiinovasi.onmicrosoft.com | E321: a4cdaa2e-caa7-440f-b849-928a3ceb7e31 | F321: AzureCSP_DivisiInovasi | G321: 1141685 | H321: SQL Database Single/ElasticPool General Purpose - Compute Gen5 | I321: =IF(LEFT(K321,9)="Standard_","Reserved Instance Virtual Machine",IF(ISNUMBER(SEARCH("SQL Database Single/ElasticPool General Purpose - Compute Gen5",K321)),"Reserved Instance SQL Database",IF(ISNUMBER(SEARCH("SQL Database SingleDB/Elastic Pool Hyperscale - Compute Gen5",K321)),"Reserved Instance Hyperscale Serverless",IF(ISNUMBER(SEARCH("Azure Database for PostgreSQL Flexible Server General Purpose Ddsv4 Series Compute",K321)),"Reserved Instance PostgreSQL",IF(ISNUMBER(SEARCH("Azure Redis Cache Premium",K321)),"Reserved Instance Redis","Reserved Instance"))))) -> Reserved Instance SQL Database | J321: SQL Database Single/ElasticPool General Purpose - Compute Gen5 | K321: =H321 -> SQL Database Single/ElasticPool General Purpose - Compute Gen5 | L321: 3 Years | M321: 3 Years | N321: =U321 -> 4 | O321: Reserved Instance | P321: IDR | Q321: Reserved Instance | R321: =IF(LEFT(K321,9)="Standard_","Virtual Machine",IF(ISNUMBER(SEARCH("SQL Database Single/ElasticPool General Purpose - Compute Gen5",K321)),"SQL Database",IF(ISNUMBER(SEARCH("SQL Database SingleDB/Elastic Pool Hyperscale - Compute Gen5",K321)),"Hyperscale Serverless",IF(ISNUMBER(SEARCH("Azure Database for PostgreSQL Flexible Server General Purpose Ddsv4 Series Compute",K321)),"PostgreSQL",IF(ISNUMBER(SEARCH("Azure Redis Cache Premium",K321)),"Redis",K321))))) -> SQL Database | S321: southeastasia | T321: Reserved Instance | U321: 4 | V321: 1001385 | W321: =U321*V321 -> 4005540 | X321: HPM
A322: May | B322: Microsoft CSP Azure Plan | C322: Divisi Inovasi | D322: divisiinovasi.onmicrosoft.com | E322: a4cdaa2e-caa7-440f-b849-928a3ceb7e33 | F322: AzureCSP_DivisiInovasi | G322: 1141685 | H322: Standard_D2s_v3 | I322: =IF(LEFT(K322,9)="Standard_","Reserved Instance Virtual Machine",IF(ISNUMBER(SEARCH("SQL Database Single/ElasticPool General Purpose - Compute Gen5",K322)),"Reserved Instance SQL Database",IF(ISNUMBER(SEARCH("SQL Database SingleDB/Elastic Pool Hyperscale - Compute Gen5",K322)),"Reserved Instance Hyperscale Serverless",IF(ISNUMBER(SEARCH("Azure Database for PostgreSQL Flexible Server General Purpose Ddsv4 Series Compute",K322)),"Reserved Instance PostgreSQL",IF(ISNUMBER(SEARCH("Azure Redis Cache Premium",K322)),"Reserved Instance Redis","Reserved Instance"))))) -> Reserved Instance Virtual Machine | J322: Standard_D2s_v3 | K322: =H322 -> Standard_D2s_v3 | L322: 3 Years | M322: 3 Years | N322: =U322 -> 1 | O322: Reserved Instance | P322: IDR | Q322: Reserved Instance | R322: =IF(LEFT(K322,9)="Standard_","Virtual Machine",IF(ISNUMBER(SEARCH("SQL Database Single/ElasticPool General Purpose - Compute Gen5",K322)),"SQL Database",IF(ISNUMBER(SEARCH("SQL Database SingleDB/Elastic Pool Hyperscale - Compute Gen5",K322)),"Hyperscale Serverless",IF(ISNUMBER(SEARCH("Azure Database for PostgreSQL Flexible Server General Purpose Ddsv4 Series Compute",K322)),"PostgreSQL",IF(ISNUMBER(SEARCH("Azure Redis Cache Premium",K322)),"Redis",K322))))) -> Virtual Machine | S322: southeastasia | T322: Reserved Instance | U322: 1 | V322: 565908.75 | W322: =U322*V322 -> 565908.75 | X322: HPM
A323: May | B323: Microsoft CSP Azure Plan | C323: Divisi Inovasi | D323: divisiinovasi.onmicrosoft.com | E323: a4cdaa2e-caa7-440f-b849-928a3ceb7e32 | F323: AzureCSP_DivisiInovasi | G323: 1141685 | H323: Standard_D4s_v3 | I323: =IF(LEFT(K323,9)="Standard_","Reserved Instance Virtual Machine",IF(ISNUMBER(SEARCH("SQL Database Single/ElasticPool General Purpose - Compute Gen5",K323)),"Reserved Instance SQL Database",IF(ISNUMBER(SEARCH("SQL Database SingleDB/Elastic Pool Hyperscale - Compute Gen5",K323)),"Reserved Instance Hyperscale Serverless",IF(ISNUMBER(SEARCH("Azure Database for PostgreSQL Flexible Server General Purpose Ddsv4 Series Compute",K323)),"Reserved Instance PostgreSQL",IF(ISNUMBER(SEARCH("Azure Redis Cache Premium",K323)),"Reserved Instance Redis","Reserved Instance"))))) -> Reserved Instance Virtual Machine | J323: Standard_D4s_v3 | K323: =H323 -> Standard_D4s_v3 | L323: 3 Years | M323: 3 Years | N323: =U323 -> 4 | O323: Reserved Instance | P323: IDR | Q323: Reserved Instance | R323: =IF(LEFT(K323,9)="Standard_","Virtual Machine",IF(ISNUMBER(SEARCH("SQL Database Single/ElasticPool General Purpose - Compute Gen5",K323)),"SQL Database",IF(ISNUMBER(SEARCH("SQL Database SingleDB/Elastic Pool Hyperscale - Compute Gen5",K323)),"Hyperscale Serverless",IF(ISNUMBER(SEARCH("Azure Database for PostgreSQL Flexible Server General Purpose Ddsv4 Series Compute",K323)),"PostgreSQL",IF(ISNUMBER(SEARCH("Azure Redis Cache Premium",K323)),"Redis",K323))))) -> Virtual Machine | S323: southeastasia | T323: Reserved Instance | U323: 4 | V323: 1131817.5 | W323: =U323*V323 -> 4527270 | X323: HPM

Sheet Detail_ITC
A1: Period | B1: Agreement Name | C1: Company Name | D1: Tenant Primary Domain | E1: Publisher Subscription ID | F1: Publisher Subscription Name | G1: Product ID | H1: Product Name | I1: Category | J1: Subcategory | K1: Meter Name | L1: Usage Start Date | M1: Usage End Date | N1: Quantity | O1: Unit | P1: Currency | Q1: Resource Group Name | R1: Resource Name | S1: Location | T1: Tags_JSON | U1: Tags_KeyValue | V1: Tags_Count | W1: Total
A2: May | B2: Microsoft CSP Azure Plan | C2: Divisi Inovasi | D2: divisiinovasi.onmicrosoft.com | E2: a4cdaa2e-caa7-440f-b849-928a3ceb7e31 | F2: AzureCSP_DivisiInovasi | G2: 1141685 | H2: VM RI | I2: Virtual Machines | J2: Virtual Machines RI | K2: Standard | L2: 46143 | M2: 46173 | N2: 0.083235 | O2: 1 Hour | P2: IDR | Q2: MC_RG-ITC_IMBE_SOUTHEASTASIA | R2: aks-systemeph-38276485-vmss | S2: southeastasia | T2: { "Organization Name": "PT Nawa Darsana Teknologi", "Publisher": "Microsoft", "Publisher Customer ID": "346fa229-7c19-44ef-85c6-29e00edf66cf", "Unit Price": "0.0", "ERP": "0.0", "BenefitType": "Charge", "aks-managed-consolidated-additional-properties": "228c5aed-ea0d-11f0-aa94-664ac880d383", "aks-managed-creationSource": "vmssclient-aks-systemeph-38276485-vmss", "aks-managed-enable-imds-restriction": "False", "aks-managed-kubeletIdentityClientID": "295ca385-8ba8-4c59-8454-74b13124e52a", "aks-managed-operationID": "98236b2d-42cf-4cc3-b5e1-77a3def373ab", "aks-managed-orchestrator": "Kubernetes:1.33.5", "aks-managed-poolName": "systemeph", "aks-managed-resourceNameSuffix": "75743100.0", "aks-managed-ssh-access": "LocalUser" } | U2: Organization Name=PT Nawa Darsana Teknologi; Publisher=Microsoft; Publisher Customer ID=346fa229-7c19-44ef-85c6-29e00edf66cf; Unit Price=0.0; ERP=0.0; BenefitType=Charge; aks-managed-consolidated-additional-properties=228c5aed-ea0d-11f0-aa94-664ac880d383; aks-managed-creationSource=vmssclient-aks-systemeph-38276485-vmss; aks-managed-enable-imds-restriction=False; aks-managed-kubeletIdentityClientID=295ca385-8ba8-4c59-8454-74b13124e52a; aks-managed-operationID=98236b2d-42cf-4cc3-b5e1-77a3def373ab; aks-managed-orchestrator=Kubernetes:1.33.5; aks-managed-poolName=systemeph; aks-managed-resourceNameSuffix=75743100.0; aks-managed-ssh-access=LocalUser | V2: 15 | W2: 0
