Workbook

Sheet Summary
B1: Detail_Anper | C1: Detail_Sinsen | D1: Detail_CDN | E1: Detail_MenaraAgung | F1: Detail_MSK | G1: Detail_HPM | H1: Detail_ITC | I1: Detail_TDM | J1: Detail_TRIO | K1: Detail_Zenobia
A2: Total Unit Price | B2: =SUM(Detail_Anper!X2:X50000) -> 9382520 | C2: =SUM(Detail_Sinsen!X2:X50000) -> 9711849.9 | D2: =SUM(Detail_CDN!X2:X50000) -> 14815754 | E2: =SUM(Detail_MenaraAgung!X2:X50000) -> 12201469 | F2: =SUM(Detail_MSK!X2:X50000) -> 9677109.3 | G2: =SUM(Detail_HPM!X2:X50000) -> 9790314.6 | H2: =SUM(Detail_ITC!X2:X50000) -> 12073972 | I2: =SUM(Detail_TDM!X2:X50000) -> 9978296.2 | J2: =SUM(Detail_TRIO!X2:X50000) -> 9767547.1 | K2: =SUM(Detail_Zenobia!X2:X50000) -> 41892851
A3: Total | B3: =SUM(Detail_Anper!W2:W50000) -> 21711306 | C3: =SUM(Detail_Sinsen!W2:W50000) -> 24708021 | D3: =SUM(Detail_CDN!W2:W50000) -> 35804792 | E3: =SUM(Detail_MenaraAgung!W2:W50000) -> 21015948 | F3: =SUM(Detail_MSK!W2:W50000) -> 21308908 | G3: =SUM(Detail_HPM!W2:W50000) -> 23126417 | H3: =SUM(Detail_ITC!W2:W50000) -> 24653784 | I3: =SUM(Detail_TDM!W2:W50000) -> 23817280 | J3: =SUM(Detail_TRIO!W2:W50000) -> 24701951 | K3: =SUM(Detail_Zenobia!W2:W50000) -> 75000128 | L3: =SUM(B3:K3) -> 2.9584854e+08

Sheet Split-Costing
A1: Resource Name | B1: Target Group | C1: Percent | D1: Allocated Unit Price | E1: Allocated Sales Unit Price | F1: Daily Split | G1: Daily Rows | H1: Top N Used
A2: frontdoor-zenobia | B2: Detail_Zenobia | C2: 30 | D2: 10189629 | E2: 11579124 | F2: yes | G2: 30 | H2: 3
A3: giant | B3: Detail_Zenobia | C3: 50 | D3: 0 | E3: 0 | F3: yes | G3: 30 | H3: 3
A4: tokyoo | B4: Detail_Zenobia | C4: 40 | D4: 6742584.1 | E4: 7662027.3 | F4: yes | G4: 30 | H4: 3
A5: fruitbasket | B5: Detail_Zenobia | C5: 10 | D5: 386503.5 | E5: 439208.53 | F5: yes | G5: 30 | H5: 3

Sheet Detail_Anper
A1: Period | B1: Agreement Name | C1: Company Name | D1: Tenant Primary Domain | E1: Publisher Subscription ID | F1: Publisher Subscription Name | G1: Product ID | H1: Product Name | I1: Category | J1: Subcategory | K1: Meter Name | L1: Usage Start Date | M1: Usage End Date | N1: Quantity | O1: Unit | P1: Currency | Q1: Resource Group Name | R1: Resource Name | S1: Location | T1: Tags_JSON | U1: Tags_KeyValue | V1: Tags_Count | W1: Total | X1: Unit Price | Y1: Price Adjustment | Z1: Sales Unit Price | AA1: Percentage Markup
A2: June | B2: Microsoft CSP Azure Plan | C2: Divisi Inovasi | D2: divisiinovasi.onmicrosoft.com | E2: a4cdaa2e-caa7-440f-b849-928a3ceb7e31 | F2: AzureCSP_DivisiInovasi | G2: 1141685 | H2: Virtual Network Peering | I2: Virtual Network | J2: Virtual Network Peering | K2: Intra-Region Egress | L2: 46174 | M2: 46203 | N2: 0.91556563 | O2: 1 GB | P2: IDR | Q2: mc_rg-anper_apricot_southeastasia | R2: aks-usereph2-32489559-vmss | S2: southeastasia | T2: { "Organization Name": "PT Nawa Darsana Teknologi", "Publisher": "Microsoft", "Publisher Customer ID": "346fa229-7c19-44ef-85c6-29e00edf66cf", "Unit Price": "157.519999997", "ERP": "163.88624777", "BenefitType": "Charge", "aks-managed-consolidated-additional-properties": "74465425-495d-11f1-ad6b-a26c3881ebea", "aks-managed-creationSource": "vmssclient-aks-usereph2-32489559-vmss", "aks-managed-enable-imds-restriction": "False", "aks-managed-kubeletIdentityClientID": "c9e56520-a8a3-452c-b5ca-cb3192dafd24", "aks-managed-operationID": "7a36d094-d16e-4088-b1a9-83b67397ae99", "aks-managed-orchestrator": "Kubernetes:1.33.5", "aks-managed-poolName": "usereph2", "aks-managed-resourceNameSuffix": "14784282.0", "aks-managed-ssh-access": "LocalUser", "compute.aks.billing": "linux" } | U2: Organization Name=PT Nawa Darsana Teknologi; Publisher=Microsoft; Publisher Customer ID=346fa229-7c19-44ef-85c6-29e00edf66cf; Unit Price=157.519999997; ERP=163.88624777; BenefitType=Charge; aks-managed-consolidated-additional-properties=74465425-495d-11f1-ad6b-a26c3881ebea; aks-managed-creationSource=vmssclient-aks-usereph2-32489559-vmss; aks-managed-enable-imds-restriction=False; aks-managed-kubeletIdentityClientID=c9e56520-a8a3-452c-b5ca-cb3192dafd24; aks-managed-operationID=7a36d094-d16e-4088-b1a9-83b67397ae99; aks-managed-orchestrator=Kubernetes:1.33.5; aks-managed-poolName=usereph2; aks-managed-resourceNameSuffix=14784282.0; aks-managed-ssh-access=LocalUser; compute.aks.billing=linux | V2: 16 | W2: 163.8899 | X2: 144.2199 | Y2: -19.67 | Z2: 163.8899 | AA2: 0.13638895
A3: June | B3: Microsoft CSP Azure Plan | C3: Divisi Inovasi | D3: divisiinovasi.onmicrosoft.com | E3: a4cdaa2e-caa7-440f-b849-928a3ceb7e31 | F3: AzureCSP_DivisiInovasi | G3: 1141685 | H3: VM RI | I3: Virtual Machines | J3: Virtual Machines RI | K3: Standard | L3: 46174 | M3: 46203 | N3: 0.249796 | O3: 1 Hour | P3: IDR | Q3: MC_RG-ANPER_APRICOT_SOUTHEASTASIA | R3: aks-systemeph-11882456-vmss | S3: southeastasia | T3: { "Organization Name": "PT Nawa Darsana Teknologi", "Publisher": "Microsoft", "Publisher Customer ID": "346fa229-7c19-44ef-85c6-29e00edf66cf", "Unit Price": "0.0", "ERP": "0.0", "BenefitType": "Charge", "aks-managed-consolidated-additional-properties": "7445f662-495d-11f1-ad6b-a26c3881ebea", "aks-managed-creationSource": "vmssclient-aks-systemeph-11882456-vmss", "aks-managed-enable-imds-restriction": "False", "aks-managed-kubeletIdentityClientID": "c9e56520-a8a3-452c-b5ca-cb3192dafd24", "aks-managed-operationID": "7a36d094-d16e-4088-b1a9-83b67397ae99", "aks-managed-orchestrator": "Kubernetes:1.33.5", "aks-managed-poolName": "systemeph", "aks-managed-resourceNameSuffix": "14784282.0", "aks-managed-ssh-access": "LocalUser", "compute.aks.billing": "linux" } | U3: Organization Name=PT Nawa Darsana Teknologi; Publisher=Microsoft; Publisher Customer ID=346fa229-7c19-44ef-85c6-29e00edf66cf; Unit Price=0.0; ERP=0.0; BenefitType=Charge; aks-managed-consolidated-additional-properties=7445f662-495d-11f1-ad6b-a26c3881ebea; aks-managed-creationSource=vmssclient-aks-systemeph-11882456-vmss; aks-managed-enable-imds-restriction=False; aks-managed-kubeletIdentityClientID=c9e56520-a8a3-452c-b5ca-cb3192dafd24; aks-managed-operationID=7a36d094-d16e-4088-b1a9-83b67397ae99; aks-managed-orchestrator=Kubernetes:1.33.5; aks-managed-poolName=systemeph; aks-managed-resourceNameSuffix=14784282.0; aks-managed-ssh-access=LocalUser; compute.aks.billing=linux | V3: 16 | W3: 0 | X3: 0 | Y3: 0 | Z3: 0
A4: June | B4: Microsoft CSP Azure Plan | C4: Divisi Inovasi | D4: divisiinovasi.onmicrosoft.com | E4: a4cdaa2e-caa7-440f-b849-928a3ceb7e31 | F4: AzureCSP_DivisiInovasi | G4: 1141685 | H4: VM RI | I4: Virtual Machines | J4: Virtual Machines RI | K4: Standard | L4: 46174 | M4: 46203 | N4: 1 | O4: 1 Hour | P4: IDR | Q4: MC_RG-ANPER_APRICOT_SOUTHEASTASIA | R4: aks-usereph2-32489559-vmss | S4: southeastasia | T4: { "Organization Name": "PT Nawa Darsana Teknologi", "Publisher": "Microsoft", "Publisher Customer ID": "346fa229-7c19-44ef-85c6-29e00edf66cf", "Unit Price": "0.0", "ERP": "0.0", "BenefitType": "Charge", "aks-managed-consolidated-additional-properties": "74465425-495d-11f1-ad6b-a26c3881ebea", "aks-managed-creationSource": "vmssclient-aks-usereph2-32489559-vmss", "aks-managed-enable-imds-restriction": "False", "aks-managed-kubeletIdentityClientID": "c9e56520-a8a3-452c-b5ca-cb3192dafd24", "aks-managed-operationID": "7a36d094-d16e-4088-b1a9-83b67397ae99", "aks-managed-orchestrator": "Kubernetes:1.33.5", "aks-managed-poolName": "usereph2", "aks-managed-resourceNameSuffix": "14784282.0", "aks-managed-ssh-access": "LocalUser", "compute.aks.billing": "linux" } | U4: Organization Name=PT Nawa Darsana Teknologi; Publisher=Microsoft; Publisher Customer ID=346fa229-7c19-44ef-85c6-29e00edf66cf; Unit Price=0.0; ERP=0.0; BenefitType=Charge; aks-managed-consolidated-additional-properties=74465425-495d-11f1-ad6b-a26c3881ebea; aks-managed-creationSource=vmssclient-aks-usereph2-32489559-vmss; aks-managed-enable-imds-restriction=False; aks-managed-kubeletIdentityClientID=c9e56520-a8a3-452c-b5ca-cb3192dafd24; aks-managed-operationID=7a36d094-d16e-4088-b1a9-83b67397ae99; aks-managed-orchestrator=Kubernetes:1.33.5; aks-managed-poolName=usereph2; aks-managed-resourceNameSuffix=14784282.0; aks-managed-ssh-access=LocalUser; compute.aks.billing=linux | V4: 16 | W4: 0 | X4: 0 | Y4: 0 | Z4: 0
A5: June | B5: Microsoft CSP Azure Plan | C5: Divisi Inovasi | D5: divisiinovasi.onmicrosoft.com | E5: a4cdaa2e-caa7-440f-b849-928a3ceb7e31 | F5: AzureCSP_DivisiInovasi | G5: 1141685 | H5: VM RI | I5: Virtual Machines | J5: Virtual Machines RI | K5: Standard | L5: 46174 | M5: 46203 | N5: 62.317726 | O5: 1 Hour | P5: IDR | Q5: MC_RG-ANPER_APRICOT_SOUTHEASTASIA | R5: aks-usereph2-32489559-vmss | S5: southeastasia | T5: { "Organization Name": "PT Nawa Darsana Teknologi", "Publisher": "Microsoft", "Publisher Customer ID": "346fa229-7c19-44ef-85c6-29e00edf66cf", "Unit Price": "0.0", "ERP": "0.0", "BenefitType": "Charge", "aks-managed-consolidated-additional-properties": "74465425-495d-11f1-ad6b-a26c3881ebea", "aks-managed-creationSource": "vmssclient-aks-usereph2-32489559-vmss", "aks-managed-enable-imds-restriction": "False", "aks-managed-kubeletIdentityClientID": "c9e56520-a8a3-452c-b5ca-cb3192dafd24", "aks-managed-operationID": "7a36d094-d16e-4088-b1a9-83b67397ae99", "aks-managed-orchestrator": "Kubernetes:1.33.5", "aks-managed-poolName": "usereph2", "aks-managed-resourceNameSuffix": "14784282.0", "aks-managed-ssh-access": "LocalUser", "compute.aks.billing": "linux" } | U5: Organization Name=PT Nawa Darsana Teknologi; Publisher=Microsoft; Publisher Customer ID=346fa229-7c19-44ef-85c6-29e00edf66cf; Unit Price=0.0; ERP=0.0; BenefitType=Charge; aks-managed-consolidated-additional-properties=74465425-495d-11f1-ad6b-a26c3881ebea; aks-managed-creationSource=vmssclient-aks-usereph2-32489559-vmss; aks-managed-enable-imds-restriction=False; aks-managed-kubeletIdentityClientID=c9e56520-a8a3-452c-b5ca-cb3192dafd24; aks-managed-operationID=7a36d094-d16e-4088-b1a9-83b67397ae99; aks-managed-orchestrator=Kubernetes:1.33.5; aks-managed-poolName=usereph2; aks-managed-resourceNameSuffix=14784282.0; aks-managed-ssh-access=LocalUser; compute.aks.billing=linux | V5: 16 | W5: 0 | X5: 0 | Y5: 0 | Z5: 0
A6: June | B6: Microsoft CSP Azure Plan | C6: Divisi Inovasi | D6: divisiinovasi.onmicrosoft.com | E6: a4cdaa2e-caa7-440f-b849-928a3ceb7e31 | F6: AzureCSP_DivisiInovasi | G6: 1141685 | H6: VM RI | I6: Virtual Machines | J6: Virtual Machines RI | K6: Standard | L6: 46174 | M6: 46203 | N6: 31.068557 | O6: 1 Hour | P6: IDR | Q6: MC_RG-ANPER_APRICOT_SOUTHEASTASIA | R6: aks-usereph2-32489559-vmss | S6: southeastasia | T6: { "Organization Name": "PT Nawa Darsana Teknologi", "Publisher": "Microsoft", "Publisher Customer ID": "346fa229-7c19-44ef-85c6-29e00edf66cf", "Unit Price": "0.0", "ERP": "0.0", "BenefitType": "Charge", "aks-managed-consolidated-additional-properties": "74465425-495d-11f1-ad6b-a26c3881ebea", "aks-managed-creationSource": "vmssclient-aks-usereph2-32489559-vmss", "aks-managed-enable-imds-restriction": "False", "aks-managed-kubeletIdentityClientID": "c9e56520-a8a3-452c-b5ca-cb3192dafd24", "aks-managed-operationID": "7a36d094-d16e-4088-b1a9-83b67397ae99", "aks-managed-orchestrator": "Kubernetes:1.33.5", "aks-managed-poolName": "usereph2", "aks-managed-resourceNameSuffix": "14784282.0", "aks-managed-ssh-access": "LocalUser", "compute.aks.billing": "linux" } | U6: Organization Name=PT Nawa Darsana Teknologi; Publisher=Microsoft; Publisher Customer ID=346fa229-7c19-44ef-85c6-29e00edf66cf; Unit Price=0.0; ERP=0.0; BenefitType=Charge; aks-managed-consolidated-additional-properties=74465425-495d-11f1-ad6b-a26c3881ebea; aks-managed-creationSource=vmssclient-aks-usereph2-32489559-vmss; aks-managed-enable-imds-restriction=False; aks-managed-kubeletIdentityClientID=c9e56520-a8a3-452c-b5ca-cb3192dafd24; aks-managed-operationID=7a36d094-d16e-4088-b1a9-83b67397ae99; aks-managed-orchestrator=Kubernetes:1.33.5; aks-managed-poolName=usereph2; aks-managed-resourceNameSuffix=14784282.0; aks-managed-ssh-access=LocalUser; compute.aks.billing=linux | V6: 16 | W6: 0 | X6: 0 | Y6: 0 | Z6: 0
A7: June | B7: Microsoft CSP Azure Plan | C7: Divisi Inovasi | D7: divisiinovasi.onmicrosoft.com | E7: a4cdaa2e-caa7-440f-b849-928a3ceb7e31 | F7: AzureCSP_DivisiInovasi | G7: 1141685 | H7: VM RI | I7: Virtual Machines | J7: Virtual Machines RI | K7: Standard | L7: 46174 | M7: 46203 | N7: 1 | O7: 1 Hour | P7: IDR | Q7: MC_RG-ANPER_APRICOT_SOUTHEASTASIA | R7: aks-usereph2-32489559-vmss | S7: southeastasia | T7: { "Organization Name": "PT Nawa Darsana Teknologi", "Publisher": "Microsoft", "Publisher Customer ID": "346fa229-7c19-44ef-85c6-29e00edf66cf", "Unit Price": "0.0", "ERP": "0.0", "BenefitType": "Charge", "aks-managed-consolidated-additional-properties": "74465425-495d-11f1-ad6b-a26c3881ebea", "aks-managed-creationSource": "vmssclient-aks-usereph2-32489559-vmss", "aks-managed-enable-imds-restriction": "False", "aks-managed-kubeletIdentityClientID": "c9e56520-a8a3-452c-b5ca-cb3192dafd24", "aks-managed-operationID": "7a36d094-d16e-4088-b1a9-83b67397ae99", "aks-managed-orchestrator": "Kubernetes:1.33.5", "aks-managed-poolName": "usereph2", "aks-managed-resourceNameSuffix": "14784282.0", "aks-managed-ssh-access": "LocalUser", "compute.aks.billing": "linux" } | U7: Organization Name=PT Nawa Darsana Teknologi; Publisher=Microsoft; Publisher Customer ID=346fa229-7c19-44ef-85c6-29e00edf66cf; Unit Price=0.0; ERP=0.0; BenefitType=Charge; aks-managed-consolidated-additional-properties=74465425-495d-11f1-ad6b-a26c3881ebea; aks-managed-creationSource=vmssclient-aks-usereph2-32489559-vmss; aks-managed-enable-imds-restriction=False; aks-managed-kubeletIdentityClientID=c9e56520-a8a3-452c-b5ca-cb3192dafd24; aks-managed-operationID=7a36d094-d16e-4088-b1a9-83b67397ae99; aks-managed-orchestrator=Kubernetes:1.33.5; aks-managed-poolName=usereph2; aks-managed-resourceNameSuffix=14784282.0; aks-managed-ssh-access=LocalUser; compute.aks.billing=linux | V7: 16 | W7: 0 | X7: 0 | Y7: 0 | Z7: 0
A8: June | B8: Microsoft CSP Azure Plan | C8: Divisi Inovasi | D8: divisiinovasi.onmicrosoft.com | E8: a4cdaa2e-caa7-440f-b849-928a3ceb7e31 | F8: AzureCSP_DivisiInovasi | G8: 1141685 | H8: SQL RI | I8: SQL Database | J8: SQL Database Compute Reservation | K8: Usage | L8: 46174 | M8: 46203 | N8: 1486 | O8: 1 Hour | P8: IDR | Q8: RG-ANPER | R8: apitalawu | S8: southeastasia | T8: { "Organization Name": "PT Nawa Darsana Teknologi", "Publisher": "Microsoft", "Publisher Customer ID": "346fa229-7c19-44ef-85c6-29e00edf66cf", "Unit Price": "0.0", "ERP": "0.0", "BenefitType": "Charge", "Anper": "CE", "MD": "Apricot", "Product": "CE" } | U8: Organization Name=PT Nawa Darsana Teknologi; Publisher=Microsoft; Publisher Customer ID=346fa229-7c19-44ef-85c6-29e00edf66cf; Unit Price=0.0; ERP=0.0; BenefitType=Charge; Anper=CE; MD=Apricot; Product=CE | V8: 9 | W8: 0 | X8: 0 | Y8: 0 | Z8: 0
A9: June | B9: Microsoft CSP Azure Plan | C9: Divisi Inovasi | D9: divisiinovasi.onmicrosoft.com | E9: a4cdaa2e-caa7-440f-b849-928a3ceb7e31 | F9: AzureCSP_DivisiInovasi | G9: 1141685 | H9: Virtual Network Private Link | I9: Virtual Network | J9: Virtual Network Private Link | K9: Standard Private Endpoint | L9: 46174 | M9: 46203 | N9: 720 | O9: 1 Hour | P9: IDR | Q9: rg-anper | R9: aks-access-to-sql-anper | S9: southeastasia | T9: { "Organization Name": "PT Nawa Darsana Teknologi", "Publisher": "Microsoft", "Publisher Customer ID": "346fa229-7c19-44ef-85c6-29e00edf66cf", "Unit Price": "157.52", "ERP": "128880.0", "BenefitType": "Charge", "Anper": "CE" } | U9: Organization Name=PT Nawa Darsana Teknologi; Publisher=Microsoft; Publisher Customer ID=346fa229-7c19-44ef-85c6-29e00edf66cf; Unit Price=157.52; ERP=128880.0; BenefitType=Charge; Anper=CE | V9: 7 | W9: 128880 | X9: 113414.4 | Y9: -15465.6 | Z9: 128880 | AA9: 0.13636364
A10: June | B10: Microsoft CSP Azure Plan | C10: Divisi Inovasi | D10: divisiinovasi.onmicrosoft.com | E10: a4cdaa2e-caa7-440f-b849-928a3ceb7e31 | F10: AzureCSP_DivisiInovasi | G10: 1141685 | H10: Bd Inter-Rgn | I10: Bandwidth | J10: Bandwidth Inter-Region | K10: Inter Continent Data Transfer Out - ASIA To Any | L10: 46174 | M10: 46203 | N10: 2.0752135 | O10: 1 GB | P10: IDR | Q10: mc_rg-anper_apricot_southeastasia | R10: aks-usereph2-32489559-vmss | S10: southeastasia | T10: { "Organization Name": "PT Nawa Darsana Teknologi", "Publisher": "Microsoft", "Publisher Customer ID": "346fa229-7c19-44ef-85c6-29e00edf66cf", "Unit Price": "1219.975146924", "ERP": "2971.70569978", "BenefitType": "Charge", "aks-managed-consolidated-additional-properties": "74465425-495d-11f1-ad6b-a26c3881ebea", "aks-managed-creationSource": "vmssclient-aks-usereph2-32489559-vmss", "aks-managed-enable-imds-restriction": "False", "aks-managed-kubeletIdentityClientID": "c9e56520-a8a3-452c-b5ca-cb3192dafd24", "aks-managed-operationID": "7a36d094-d16e-4088-b1a9-83b67397ae99", "aks-managed-orchestrator": "Kubernetes:1.33.5", "aks-managed-poolName": "usereph2", "aks-managed-resourceNameSuffix": "14784282.0", "aks-managed-ssh-access": "LocalUser", "compute.aks.billing": "linux" } | U10: Organization Name=PT Nawa Darsana Teknologi; Publisher=Microsoft; Publisher Customer ID=346fa229-7c19-44ef-85c6-29e00edf66cf; Unit Price=1219.975146924; ERP=2971.70569978; BenefitType=Charge; aks-managed-consolidated-additional-properties=74465425-495d-11f1-ad6b-a26c3881ebea; aks-managed-creationSource=vmssclient-aks-usereph2-32489559-vmss; aks-managed-enable-imds-restriction=False; aks-managed-kubeletIdentityClientID=c9e56520-a8a3-452c-b5ca-cb3192dafd24; aks-managed-operationID=7a36d094-d16e-4088-b1a9-83b67397ae99; aks-managed-orchestrator=Kubernetes:1.33.5; aks-managed-poolName=usereph2; aks-managed-resourceNameSuffix=14784282.0; aks-managed-ssh-access=LocalUser; compute.aks.billing=linux | V10: 16 | W10: 2876.9389 | X10: 2531.7089 | Y10: -345.23 | Z10: 2876.9389 | AA10: 0.13636244
A11: June | B11: Microsoft CSP Azure Plan | C11: Divisi Inovasi | D11: divisiinovasi.onmicrosoft.com | E11: a4cdaa2e-caa7-440f-b849-928a3ceb7e31 | F11: AzureCSP_DivisiInovasi | G11: 1141685 | H11: Bd Inter-Rgn | I11: Bandwidth | J11: Bandwidth Inter-Region | K11: Inter Continent Data Transfer Out - ASIA To Any | L11: 46174 | M11: 46203 | N11: 0.56531116 | O11: 1 GB | P11: IDR | Q11: mc_rg-anper_apricot_southeastasia | R11: aks-systemeph-11882456-vmss | S11: southeastasia | T11: { "Organization Name": "PT Nawa Darsana Teknologi", "Publisher": "Microsoft", "Publisher Customer ID": "346fa229-7c19-44ef-85c6-29e00edf66cf", "Unit Price": "1216.2665296853", "ERP": "809.5255847", "BenefitType": "Charge", "aks-managed-consolidated-additional-properties": "7445f662-495d-11f1-ad6b-a26c3881ebea", "aks-managed-creationSource": "vmssclient-aks-systemeph-11882456-vmss", "aks-managed-enable-imds-restriction": "False", "aks-managed-kubeletIdentityClientID": "c9e56520-a8a3-452c-b5ca-cb3192dafd24", "aks-managed-operationID": "7a36d094-d16e-4088-b1a9-83b67397ae99", "aks-managed-orchestrator": "Kubernetes:1.33.5", "aks-managed-poolName": "systemeph", "aks-managed-resourceNameSuffix": "14784282.0", "aks-managed-ssh-access": "LocalUser", "compute.aks.billing": "linux" } | U11: Organization Name=PT Nawa Darsana Teknologi; Publisher=Microsoft; Publisher Customer ID=346fa229-7c19-44ef-85c6-29e00edf66cf; Unit Price=1216.2665296853; ERP=809.5255847; BenefitType=Charge; aks-managed-consolidated-additional-properties=7445f662-495d-11f1-ad6b-a26c3881ebea; aks-managed-creationSource=vmssclient-aks-systemeph-11882456-vmss; aks-managed-enable-imds-restriction=False; aks-managed-kubeletIdentityClientID=c9e56520-a8a3-452c-b5ca-cb3192dafd24; aks-managed-operationID=7a36d094-d16e-4088-b1a9-83b67397ae99; aks-managed-orchestrator=Kubernetes:1.33.5; aks-managed-poolName=systemeph; aks-managed-resourceNameSuffix=14784282.0; aks-managed-ssh-access=LocalUser; compute.aks.billing=linux | V11: 16 | W11: 781.32905 | X11: 687.56905 | Y11: -93.76 | Z11: 781.32905 | AA11: 0.13636449
A12: June | B12: Microsoft CSP Azure Plan | C12: Divisi Inovasi | D12: divisiinovasi.onmicrosoft.com | E12: a4cdaa2e-caa7-440f-b849-928a3ceb7e31 | F12: AzureCSP_DivisiInovasi | G12: 1141685 | H12: Bd Inter-Rgn | I12: Bandwidth | J12: Bandwidth Inter-Region | K12: Inter Continent Data Transfer Out - ASIA To Any | L12: 46174 | M12: 46203 | N12: 1.6809735 | O12: 1 GB | P12: IDR | Q12: mc_rg-anper_apricot_southeastasia | R12: aks-usereph2-32489559-vmss | S12: southeastasia | T12: { "Organization Name": "PT Nawa Darsana Teknologi", "Publisher": "Microsoft", "Publisher Customer ID": "346fa229-7c19-44ef-85c6-29e00edf66cf", "Unit Price": "1212.212109605", "ERP": "2407.15400904", "BenefitType": "Charge", "aks-managed-consolidated-additional-properties": "74465425-495d-11f1-ad6b-a26c3881ebea", "aks-managed-creationSource": "vmssclient-aks-usereph2-32489559-vmss", "aks-managed-enable-imds-restriction": "False", "aks-managed-kubeletIdentityClientID": "c9e56520-a8a3-452c-b5ca-cb3192dafd24", "aks-managed-operationID": "7a36d094-d16e-4088-b1a9-83b67397ae99", "aks-managed-orchestrator": "Kubernetes:1.33.5", "aks-managed-poolName": "usereph2", "aks-managed-resourceNameSuffix": "14784282.0", "aks-managed-ssh-access": "LocalUser", "compute.aks.billing": "linux" } | U12: Organization Name=PT Nawa Darsana Teknologi; Publisher=Microsoft; Publisher Customer ID=346fa229-7c19-44ef-85c6-29e00edf66cf; Unit Price=1212.212109605; ERP=2407.15400904; BenefitType=Charge; aks-managed-consolidated-additional-properties=74465425-495d-11f1-ad6b-a26c3881ebea; aks-managed-creationSource=vmssclient-aks-usereph2-32489559-vmss; aks-managed-enable-imds-restriction=False; aks-managed-kubeletIdentityClientID=c9e56520-a8a3-452c-b5ca-cb3192dafd24; aks-managed-operationID=7a36d094-d16e-4088-b1a9-83b67397ae99; aks-managed-orchestrator=Kubernetes:1.33.5; aks-managed-poolName=usereph2; aks-managed-resourceNameSuffix=14784282.0; aks-managed-ssh-access=LocalUser; compute.aks.billing=linux | V12: 16 | W12: 2315.5664 | X12: 2037.6964 | Y12: -277.87 | Z12: 2315.5664 | AA12: 0.13636477
A13: June | B13: Microsoft CSP Azure Plan | C13: Divisi Inovasi | D13: divisiinovasi.onmicrosoft.com | E13: a4cdaa2e-caa7-440f-b849-928a3ceb7e31 | F13: AzureCSP_DivisiInovasi | G13: 1141685 | H13: Virtual Network Private Link | I13: Virtual Network | J13: Virtual Network Private Link | K13: Standard Data Processed - Egress | L13: 46174 | M13: 46203 | N13: 2.5311907 | O13: 1 GB | P13: IDR | Q13: mc_rg-anper_apricot_southeastasia | R13: aks-systemeph-11882456-vmss | S13: southeastasia | T13: { "Organization Name": "PT Nawa Darsana Teknologi", "Publisher": "Microsoft", "Publisher Customer ID": "346fa229-7c19-44ef-85c6-29e00edf66cf", "Unit Price": "157.5199999989", "ERP": "453.08313351", "BenefitType": "Charge", "aks-managed-consolidated-additional-properties": "7445f662-495d-11f1-ad6b-a26c3881ebea", "aks-managed-creationSource": "vmssclient-aks-systemeph-11882456-vmss", "aks-managed-enable-imds-restriction": "False", "aks-managed-kubeletIdentityClientID": "c9e56520-a8a3-452c-b5ca-cb3192dafd24", "aks-managed-operationID": "7a36d094-d16e-4088-b1a9-83b67397ae99", "aks-managed-orchestrator": "Kubernetes:1.33.5", "aks-managed-poolName": "systemeph", "aks-managed-resourceNameSuffix": "14784282.0", "aks-managed-ssh-access": "LocalUser", "compute.aks.billing": "linux" } | U13: Organization Name=PT Nawa Darsana Teknologi; Publisher=Microsoft; Publisher Customer ID=346fa229-7c19-44ef-85c6-29e00edf66cf; Unit Price=157.5199999989; ERP=453.08313351; BenefitType=Charge; aks-managed-consolidated-additional-properties=7445f662-495d-11f1-ad6b-a26c3881ebea; aks-managed-creationSource=vmssclient-aks-systemeph-11882456-vmss; aks-managed-enable-imds-restriction=False; aks-managed-kubeletIdentityClientID=c9e56520-a8a3-452c-b5ca-cb3192dafd24; aks-managed-operationID=7a36d094-d16e-4088-b1a9-83b67397ae99; aks-managed-orchestrator=Kubernetes:1.33.5; aks-managed-poolName=systemeph; aks-managed-resourceNameSuffix=14784282.0; aks-managed-ssh-access=LocalUser; compute.aks.billing=linux | V13: 16 | W13: 453.08316 | X13: 398.71316 | Y13: -54.37 | Z13: 453.08316 | AA13: 0.1363637
A14: June | B14: Microsoft CSP Azure Plan | C14: Divisi Inovasi | D14: divisiinovasi.onmicrosoft.com | E14: a4cdaa2e-caa7-440f-b849-928a3ceb7e31 | F14: AzureCSP_DivisiInovasi | G14: 1141685 | H14: Virtual Network Private Link | I14: Virtual Network | J14: Virtual Network Private Link | K14: Standard Data Processed - Egress | L14: 46174 | M14: 46203 | N14: 30.364177 | O14: 1 GB | P14: IDR | Q14: mc_rg-anper_apricot_southeastasia | R14: aks-usereph2-32489559-vmss | S14: southeastasia | T14: { "Organization Name": "PT Nawa Darsana Teknologi", "Publisher": "Microsoft", "Publisher Customer ID": "346fa229-7c19-44ef-85c6-29e00edf66cf", "Unit Price": "157.5199999999", "ERP": "5435.18775102", "BenefitType": "Charge", "aks-managed-consolidated-additional-properties": "74465425-495d-11f1-ad6b-a26c3881ebea", "aks-managed-creationSource": "vmssclient-aks-usereph2-32489559-vmss", "aks-managed-enable-imds-restriction": "False", "aks-managed-kubeletIdentityClientID": "c9e56520-a8a3-452c-b5ca-cb3192dafd24", "aks-managed-operationID": "7a36d094-d16e-4088-b1a9-83b67397ae99", "aks-managed-orchestrator": "Kubernetes:1.33.5", "aks-managed-poolName": "usereph2", "aks-managed-resourceNameSuffix": "14784282.0", "aks-managed-ssh-access": "LocalUser", "compute.aks.billing": "linux" } | U14: Organization Name=PT Nawa Darsana Teknologi; Publisher=Microsoft; Publisher Customer ID=346fa229-7c19-44ef-85c6-29e00edf66cf; Unit Price=157.5199999999; ERP=5435.18775102; BenefitType=Charge; aks-managed-consolidated-additional-properties=74465425-495d-11f1-ad6b-a26c3881ebea; aks-managed-creationSource=vmssclient-aks-usereph2-32489559-vmss; aks-managed-enable-imds-restriction=False; aks-managed-kubeletIdentityClientID=c9e56520-a8a3-452c-b5ca-cb3192dafd24; aks-managed-operationID=7a36d094-d16e-4088-b1a9-83b67397ae99; aks-managed-orchestrator=Kubernetes:1.33.5; aks-managed-poolName=usereph2; aks-managed-resourceNameSuffix=14784282.0; aks-managed-ssh-access=LocalUser; compute.aks.billing=linux | V14: 16 | W14: 5435.1852 | X14: 4782.9652 | Y14: -652.22 | Z14: 5435.1852 | AA14: 0.13636311
A15: June | B15: Microsoft CSP Azure Plan | C15: Divisi Inovasi | D15: divisiinovasi.onmicrosoft.com | E15: a4cdaa2e-caa7-440f-b849-928a3ceb7e31 | F15: AzureCSP_DivisiInovasi | G15: 1141685 | H15: Bd Inter-Rgn | I15: Bandwidth | J15: Bandwidth Inter-Region | K15: Inter Continent Data Transfer Out - ASIA To Any | L15: 46174 | M15: 46203 | N15: 0.3690117 | O15: 1 GB | P15: IDR | Q15: mc_rg-anper_apricot_southeastasia | R15: aks-monitoring-44423715-vmss | S15: southeastasia | T15: { "Organization Name": "PT Nawa Darsana Teknologi", "Publisher": "Microsoft", "Publisher Customer ID": "346fa229-7c19-44ef-85c6-29e00edf66cf", "Unit Price": "1227.0015197479", "ERP": "528.42475082", "BenefitType": "Charge", "aks-managed-consolidated-additional-properties": "744593b0-495d-11f1-ad6b-a26c3881ebea", "aks-managed-creationSource": "vmssclient-aks-monitoring-44423715-vmss", "aks-managed-enable-imds-restriction": "False", "aks-managed-kubeletIdentityClientID": "c9e56520-a8a3-452c-b5ca-cb3192dafd24", "aks-managed-operationID": "7a36d094-d16e-4088-b1a9-83b67397ae99", "aks-managed-orchestrator": "Kubernetes:1.33.5", "aks-managed-poolName": "monitoring", "aks-managed-resourceNameSuffix": "14784282.0", "aks-managed-ssh-access": "LocalUser", "compute.aks.billing": "linux", "purpose": "monitoring" } | U15: Organization Name=PT Nawa Darsana Teknologi; Publisher=Microsoft; Publisher Customer ID=346fa229-7c19-44ef-85c6-29e00edf66cf; Unit Price=1227.0015197479; ERP=528.42475082; BenefitType=Charge; aks-managed-consolidated-additional-properties=744593b0-495d-11f1-ad6b-a26c3881ebea; aks-managed-creationSource=vmssclient-aks-monitoring-44423715-vmss; aks-managed-enable-imds-restriction=False; aks-managed-kubeletIdentityClientID=c9e56520-a8a3-452c-b5ca-cb3192dafd24; aks-managed-operationID=7a36d094-d16e-4088-b1a9-83b67397ae99; aks-managed-orchestrator=Kubernetes:1.33.5; aks-managed-poolName=monitoring; aks-managed-resourceNameSuffix=14784282.0; aks-managed-ssh-access=LocalUser; compute.aks.billing=linux; purpose=monitoring | V15: 17 | W15: 514.51791 | X15: 452.77791 | Y15: -61.74 | Z15: 514.51791 | AA15: 0.13635824
A16: June | B16: Microsoft CSP Azure Plan | C16: Divisi Inovasi | D16: divisiinovasi.onmicrosoft.com | E16: a4cdaa2e-caa7-440f-b849-928a3ceb7e31 | F16: AzureCSP_DivisiInovasi | G16: 1141685 | H16: Microsoft Def for SQL | I16: Microsoft Defender for Cloud | J16: Microsoft Defender for SQL | K16: Standard Node | L16: 46174 | M16: 46203 | N16: 0.96774194 | O16: 1/Month | P16: IDR | Q16: RG-ANPER | R16: apangcoe | S16: southeastasia | T16: { "Organization Name": "PT Nawa Darsana Teknologi", "Publisher": "Microsoft", "Publisher Customer ID": "346fa229-7c19-44ef-85c6-29e00edf66cf", "Unit Price": "236279.9999999971", "ERP": "259838.70967638", "BenefitType": "Charge", "Anper": "CE", "md-alias": "Anper", "Product": "CE" } | U16: Organization Name=PT Nawa Darsana Teknologi; Publisher=Microsoft; Publisher Customer ID=346fa229-7c19-44ef-85c6-29e00edf66cf; Unit Price=236279.9999999971; ERP=259838.70967638; BenefitType=Charge; Anper=CE; md-alias=Anper; Product=CE | V16: 9 | W16: 259838.71 | X16: 228658.06 | Y16: -31180.65 | Z16: 259838.71 | AA16: 0.13636366
A17: June | B17: Microsoft CSP Azure Plan | C17: Divisi Inovasi | D17: divisiinovasi.onmicrosoft.com | E17: a4cdaa2e-caa7-440f-b849-928a3ceb7e31 | F17: AzureCSP_DivisiInovasi | G17: 1141685 | H17: Bd Inter-Rgn | I17: Bandwidth | J17: Bandwidth Inter-Region | K17: Inter Continent Data Transfer Out - ASIA To Any | L17: 46174 | M17: 46203 | N17: 8.74726e-05 | O17: 1 GB | P17: IDR | Q17: mc_rg-anper_apricot_southeastasia | R17: aks-usereph2-32489559-vmss | S17: southeastasia | T17: { "Organization Name": "PT Nawa Darsana Teknologi", "Publisher": "Microsoft", "Publisher Customer ID": "346fa229-7c19-44ef-85c6-29e00edf66cf", "Unit Price": "1260.1599995887", "ERP": "0.12526062", "BenefitType": "Charge", "aks-managed-consolidated-additional-properties": "74465425-495d-11f1-ad6b-a26c3881ebea", "aks-managed-creationSource": "vmssclient-aks-usereph2-32489559-vmss", "aks-managed-enable-imds-restriction": "False", "aks-managed-kubeletIdentityClientID": "c9e56520-a8a3-452c-b5ca-cb3192dafd24", "aks-managed-operationID": "7a36d094-d16e-4088-b1a9-83b67397ae99", "aks-managed-orchestrator": "Kubernetes:1.33.5", "aks-managed-poolName": "usereph2", "aks-managed-resourceNameSuffix": "14784282.0", "aks-managed-ssh-access": "LocalUser", "compute.aks.billing": "linux" } | U17: Organization Name=PT Nawa Darsana Teknologi; Publisher=Microsoft; Publisher Customer ID=346fa229-7c19-44ef-85c6-29e00edf66cf; Unit Price=1260.1599995887; ERP=0.12526062; BenefitType=Charge; aks-managed-consolidated-additional-properties=74465425-495d-11f1-ad6b-a26c3881ebea; aks-managed-creationSource=vmssclient-aks-usereph2-32489559-vmss; aks-managed-enable-imds-restriction=False; aks-managed-kubeletIdentityClientID=c9e56520-a8a3-452c-b5ca-cb3192dafd24; aks-managed-operationID=7a36d094-d16e-4088-b1a9-83b67397ae99; aks-managed-orchestrator=Kubernetes:1.33.5; aks-managed-poolName=usereph2; aks-managed-resourceNameSuffix=14784282.0; aks-managed-ssh-access=LocalUser; compute.aks.billing=linux | V17: 16 | W17: 0.13022948 | X17: 0.11022948 | Y17: -0.02 | Z17: 0.13022948 | AA17: 0.18143966
A18: June | B18: Microsoft CSP Azure Plan | C18: Divisi Inovasi | D18: divisiinovasi.onmicrosoft.com | E18: a4cdaa2e-caa7-440f-b849-928a3ceb7e31 | F18: AzureCSP_DivisiInovasi | G18: 1141685 | H18: Azure Monitor | I18: Azure Monitor | J18: Azure Monitor | K18: Standard Web Test Execution | L18: 46174 | M18: 46203 | N18: 198720 | O18: 1 | P18: IDR | Q18: RG-ANPER | R18: api-curl-anper | S18: indonesiacentral | T18: { "Organization Name": "PT Nawa Darsana Teknologi", "Publisher": "Microsoft", "Publisher Customer ID": "346fa229-7c19-44ef-85c6-29e00edf66cf", "Unit Price": "9.21492", "ERP": "2080896.48", "BenefitType": "Charge" } | U18: Organization Name=PT Nawa Darsana Teknologi; Publisher=Microsoft; Publisher Customer ID=346fa229-7c19-44ef-85c6-29e00edf66cf; Unit Price=9.21492; ERP=2080896.48; BenefitType=Charge | V18: 6 | W18: 2080896.5 | X18: 1831188.9 | Y18: -249707.58 | Z18: 2080896.5 | AA18: 0.13636364
A19: June | B19: Microsoft CSP Azure Plan | C19: Divisi Inovasi | D19: divisiinovasi.onmicrosoft.com | E19: a4cdaa2e-caa7-440f-b849-928a3ceb7e31 | F19: AzureCSP_DivisiInovasi | G19: 1141685 | H19: Service Bus | I19: Service Bus | J19: Service Bus | K19: Standard Messaging Operations | L19: 46174 | M19: 46203 | N19: 0.000339 | O19: 1M | P19: IDR | Q19: RG-ANPER | R19: azaleahub | S19: southeastasia | T19: { "Organization Name": "PT Nawa Darsana Teknologi", "Publisher": "Microsoft", "Publisher Customer ID": "346fa229-7c19-44ef-85c6-29e00edf66cf", "Unit Price": "0.0", "ERP": "4.85448", "BenefitType": "Charge", "Anper": "Anper", "CE": "CDC" } | U19: Organization Name=PT Nawa Darsana Teknologi; Publisher=Microsoft; Publisher Customer ID=346fa229-7c19-44ef-85c6-29e00edf66cf; Unit Price=0.0; ERP=4.85448; BenefitType=Charge; Anper=Anper; CE=CDC | V19: 8 | W19: 0 | X19: 0 | Y19: 0 | Z19: 0
A20: June | B20: Microsoft CSP Azure Plan | C20: Divisi Inovasi | D20: divisiinovasi.onmicrosoft.com | E20: a4cdaa2e-caa7-440f-b849-928a3ceb7e31 | F20: AzureCSP_DivisiInovasi | G20: 1141685 | H20: Dv3 Series VM | I20: Virtual Machines | J20: Virtual Machines Dv3 Series | K20: D4 v3/D4s v3 | L20: 46174 | M20: 46203 | N20: 1 | O20: 1 Hour | P20: IDR | Q20: MC_RG-ANPER_APRICOT_SOUTHEASTASIA | R20: aks-usereph2-32489559-vmss | S20: southeastasia | T20: { "Organization Name": "PT Nawa Darsana Teknologi", "Publisher": "Microsoft", "Publisher Customer ID": "346fa229-7c19-44ef-85c6-29e00edf66cf", "Unit Price": "3938.0", "ERP": "4475.0", "BenefitType": "Charge", "aks-managed-consolidated-additional-properties": "74465425-495d-11f1-ad6b-a26c3881ebea", "aks-managed-creationSource": "vmssclient-aks-usereph2-32489559-vmss", "aks-managed-enable-imds-restriction": "False", "aks-managed-kubeletIdentityClientID": "c9e56520-a8a3-452c-b5ca-cb3192dafd24", "aks-managed-operationID": "7a36d094-d16e-4088-b1a9-83b67397ae99", "aks-managed-orchestrator": "Kubernetes:1.33.5", "aks-managed-poolName": "usereph2", "aks-managed-resourceNameSuffix": "14784282.0", "aks-managed-ssh-access": "LocalUser", "compute.aks.billing": "linux" } | U20: Organization Name=PT Nawa Darsana Teknologi; Publisher=Microsoft; Publisher Customer ID=346fa229-7c19-44ef-85c6-29e00edf66cf; Unit Price=3938.0; ERP=4475.0; BenefitType=Charge; aks-managed-consolidated-additional-properties=74465425-495d-11f1-ad6b-a26c3881ebea; aks-managed-creationSource=vmssclient-aks-usereph2-32489559-vmss; aks-managed-enable-imds-restriction=False; aks-managed-kubeletIdentityClientID=c9e56520-a8a3-452c-b5ca-cb3192dafd24; aks-managed-operationID=7a36d094-d16e-4088-b1a9-83b67397ae99; aks-managed-orchestrator=Kubernetes:1.33.5; aks-managed-poolName=usereph2; aks-managed-resourceNameSuffix=14784282.0; aks-managed-ssh-access=LocalUser; compute.aks.billing=linux | V20: 16 | W20: 4475 | X20: 3938 | Y20: -537 | Z20: 4475 | AA20: 0.13636364
A21: June | B21: Microsoft CSP Azure Plan | C21: Divisi Inovasi | D21: divisiinovasi.onmicrosoft.com | E21: a4cdaa2e-caa7-440f-b849-928a3ceb7e31 | F21: AzureCSP_DivisiInovasi | G21: 1141685 | H21: SQL DB Sgl/El Pool PITR Backup Storage | I21: SQL Database | J21: SQL Database Single/Elastic Pool PITR Backup Storage | K21: RA-GRS Data Stored | L21: 46174 | M21: 46203 | N21: 0.16633572 | O21: 1 GB/Month | P21: IDR | Q21: RG-ANPER | R21: apitalawu | S21: southeastasia | T21: { "Organization Name": "PT Nawa Darsana Teknologi", "Publisher": "Microsoft", "Publisher Customer ID": "346fa229-7c19-44ef-85c6-29e00edf66cf", "Unit Price": "3780.4799999993", "ERP": "714.57825491", "BenefitType": "Charge", "Anper": "CE", "MD": "Apricot", "Product": "CE" } | U21: Organization Name=PT Nawa Darsana Teknologi; Publisher=Microsoft; Publisher Customer ID=346fa229-7c19-44ef-85c6-29e00edf66cf; Unit Price=3780.4799999993; ERP=714.57825491; BenefitType=Charge; Anper=CE; MD=Apricot; Product=CE | V21: 9 | W21: 714.57886 | X21: 628.82886 | Y21: -85.75 | Z21: 714.57886 | AA21: 0.13636461
A22: June | B22: Microsoft CSP Azure Plan | C22: Divisi Inovasi | D22: divisiinovasi.onmicrosoft.com | E22: a4cdaa2e-caa7-440f-b849-928a3ceb7e31 | F22: AzureCSP_DivisiInovasi | G22: 1141685 | H22: Rtn Pref: MGN | I22: Bandwidth | J22: Rtn Preference: MGN | K22: Standard Data Transfer Out | L22: 46174 | M22: 46203 | N22: 2.3375997 | O22: 1 GB | P22: IDR | Q22: mc_rg-anper_apricot_southeastasia | R22: aks-monitoring-44423715-vmss | S22: southeastasia | T22: { "Organization Name": "PT Nawa Darsana Teknologi", "Publisher": "Microsoft", "Publisher Customer ID": "346fa229-7c19-44ef-85c6-29e00edf66cf", "Unit Price": "1855.9473910116", "ERP": "5021.16426121", "BenefitType": "Charge", "aks-managed-consolidated-additional-properties": "744593b0-495d-11f1-ad6b-a26c3881ebea", "aks-managed-creationSource": "vmssclient-aks-monitoring-44423715-vmss", "aks-managed-enable-imds-restriction": "False", "aks-managed-kubeletIdentityClientID": "c9e56520-a8a3-452c-b5ca-cb3192dafd24", "aks-managed-operationID": "7a36d094-d16e-4088-b1a9-83b67397ae99", "aks-managed-orchestrator": "Kubernetes:1.33.5", "aks-managed-poolName": "monitoring", "aks-managed-resourceNameSuffix": "14784282.0", "aks-managed-ssh-access": "LocalUser", "compute.aks.billing": "linux", "purpose": "monitoring" } | U22: Organization Name=PT Nawa Darsana Teknologi; Publisher=Microsoft; Publisher Customer ID=346fa229-7c19-44ef-85c6-29e00edf66cf; Unit Price=1855.9473910116; ERP=5021.16426121; BenefitType=Charge; aks-managed-consolidated-additional-properties=744593b0-495d-11f1-ad6b-a26c3881ebea; aks-managed-creationSource=vmssclient-aks-monitoring-44423715-vmss; aks-managed-enable-imds-restriction=False; aks-managed-kubeletIdentityClientID=c9e56520-a8a3-452c-b5ca-cb3192dafd24; aks-managed-operationID=7a36d094-d16e-4088-b1a9-83b67397ae99; aks-managed-orchestrator=Kubernetes:1.33.5; aks-managed-poolName=monitoring; aks-managed-resourceNameSuffix=14784282.0; aks-managed-ssh-access=LocalUser; compute.aks.billing=linux; purpose=monitoring | V22: 17 | W22: 4930.0722 | X22: 4338.4622 | Y22: -591.61 | Z22: 4930.0722 | AA22: 0.13636399
A23: June | B23: Microsoft CSP Azure Plan | C23: Divisi Inovasi | D23: divisiinovasi.onmicrosoft.com | E23: a4cdaa2e-caa7-440f-b849-928a3ceb7e31 | F23: AzureCSP_DivisiInovasi | G23: 1141685 | H23: Rtn Pref: MGN | I23: Bandwidth | J23: Rtn Preference: MGN | K23: Standard Data Transfer Out | L23: 46174 | M23: 46203 | N23: 0.33164177 | O23: 1 GB | P23: IDR | Q23: mc_rg-anper_apricot_southeastasia | R23: aks-usereph2-32489559-vmss | S23: southeastasia | T23: { "Organization Name": "PT Nawa Darsana Teknologi", "Publisher": "Microsoft", "Publisher Customer ID": "346fa229-7c19-44ef-85c6-29e00edf66cf", "Unit Price": "1874.6866190307", "ERP": "712.36652733", "BenefitType": "Charge", "aks-managed-consolidated-additional-properties": "74465425-495d-11f1-ad6b-a26c3881ebea", "aks-managed-creationSource": "vmssclient-aks-usereph2-32489559-vmss", "aks-managed-enable-imds-restriction": "False", "aks-managed-kubeletIdentityClientID": "c9e56520-a8a3-452c-b5ca-cb3192dafd24", "aks-managed-operationID": "7a36d094-d16e-4088-b1a9-83b67397ae99", "aks-managed-orchestrator": "Kubernetes:1.33.5", "aks-managed-poolName": "usereph2", "aks-managed-resourceNameSuffix": "14784282.0", "aks-managed-ssh-access": "LocalUser", "compute.aks.billing": "linux" } | U23: Organization Name=PT Nawa Darsana Teknologi; Publisher=Microsoft; Publisher Customer ID=346fa229-7c19-44ef-85c6-29e00edf66cf; Unit Price=1874.6866190307; ERP=712.36652733; BenefitType=Charge; aks-managed-consolidated-additional-properties=74465425-495d-11f1-ad6b-a26c3881ebea; aks-managed-creationSource=vmssclient-aks-usereph2-32489559-vmss; aks-managed-enable-imds-restriction=False; aks-managed-kubeletIdentityClientID=c9e56520-a8a3-452c-b5ca-cb3192dafd24; aks-managed-operationID=7a36d094-d16e-4088-b1a9-83b67397ae99; aks-managed-orchestrator=Kubernetes:1.33.5; aks-managed-poolName=usereph2; aks-managed-resourceNameSuffix=14784282.0; aks-managed-ssh-access=LocalUser; compute.aks.billing=linux | V23: 16 | W23: 706.50439 | X23: 621.72439 | Y23: -84.78 | Z23: 706.50439 | AA23: 0.13636267
A24: June | B24: Microsoft CSP Azure Plan | C24: Divisi Inovasi | D24: divisiinovasi.onmicrosoft.com | E24: a4cdaa2e-caa7-440f-b849-928a3ceb7e31 | F24: AzureCSP_DivisiInovasi | G24: 1141685 | H24: Azure DNS | I24: Azure DNS | J24: Azure DNS | K24: Private Zone | L24: 46174 | M24: 46203 | N24: 0.96774194 | O24: 1 | P24: IDR | Q24: rg-anper | R24: privatelink.database.windows.net | S24: global | T24: { "Organization Name": "PT Nawa Darsana Teknologi", "Publisher": "Microsoft", "Publisher Customer ID": "346fa229-7c19-44ef-85c6-29e00edf66cf", "Unit Price": "2450.3111111099", "ERP": "8661.29032183", "BenefitType": "Charge", "Anper": "CE" } | U24: Organization Name=PT Nawa Darsana Teknologi; Publisher=Microsoft; Publisher Customer ID=346fa229-7c19-44ef-85c6-29e00edf66cf; Unit Price=2450.3111111099; ERP=8661.29032183; BenefitType=Charge; Anper=CE | V24: 7 | W24: 2694.6188 | X24: 2371.2688 | Y24: -323.35 | Z24: 2694.6188 | AA24: 0.1363616
A25: June | B25: Microsoft CSP Azure Plan | C25: Divisi Inovasi | D25: divisiinovasi.onmicrosoft.com | E25: a4cdaa2e-caa7-440f-b849-928a3ceb7e31 | F25: AzureCSP_DivisiInovasi | G25: 1141685 | H25: Virtual Network Private Link | I25: Virtual Network | J25: Virtual Network Private Link | K25: Standard Private Endpoint | L25: 46174 | M25: 46203 | N25: 720 | O25: 1 Hour | P25: IDR | Q25: rg-anper | R25: azaleahub-to-aks-salvia-private-endpoint | S25: southeastasia | T25: { "Organization Name": "PT Nawa Darsana Teknologi", "Publisher": "Microsoft", "Publisher Customer ID": "346fa229-7c19-44ef-85c6-29e00edf66cf", "Unit Price": "157.52", "ERP": "128880.0", "BenefitType": "Charge", "Anper": "Anper", "CE": "CDC" } | U25: Organization Name=PT Nawa Darsana Teknologi; Publisher=Microsoft; Publisher Customer ID=346fa229-7c19-44ef-85c6-29e00edf66cf; Unit Price=157.52; ERP=128880.0; BenefitType=Charge; Anper=Anper; CE=CDC | V25: 8 | W25: 128880 | X25: 113414.4 | Y25: -15465.6 | Z25: 128880 | AA25: 0.13636364
A26: June | B26: Microsoft CSP Azure Plan | C26: Divisi Inovasi | D26: divisiinovasi.onmicrosoft.com | E26: a4cdaa2e-caa7-440f-b849-928a3ceb7e31 | F26: AzureCSP_DivisiInovasi | G26: 1141685 | H26: Virtual Network Private Link | I26: Virtual Network | J26: Virtual Network Private Link | K26: Standard Private Endpoint | L26: 46174 | M26: 46203 | N26: 720 | O26: 1 Hour | P26: IDR | Q26: rg-anper | R26: sql-anper-to-aks-salvia-private-endpoint | S26: southeastasia | T26: { "Organization Name": "PT Nawa Darsana Teknologi", "Publisher": "Microsoft", "Publisher Customer ID": "346fa229-7c19-44ef-85c6-29e00edf66cf", "Unit Price": "157.52", "ERP": "128880.0", "BenefitType": "Charge", "Anper": "Anper" } | U26: Organization Name=PT Nawa Darsana Teknologi; Publisher=Microsoft; Publisher Customer ID=346fa229-7c19-44ef-85c6-29e00edf66cf; Unit Price=157.52; ERP=128880.0; BenefitType=Charge; Anper=Anper | V26: 7 | W26: 128880 | X26: 113414.4 | Y26: -15465.6 | Z26: 128880 | AA26: 0.13636364
A27: June | B27: Microsoft CSP Azure Plan | C27: Divisi Inovasi | D27: divisiinovasi.onmicrosoft.com | E27: a4cdaa2e-caa7-440f-b849-928a3ceb7e31 | F27: AzureCSP_DivisiInovasi | G27: 1141685 | H27: Virtual Network Private Link | I27: Virtual Network | J27: Virtual Network Private Link | K27: Standard Private Endpoint | L27: 46174 | M27: 46203 | N27: 720 | O27: 1 Hour | P27: IDR | Q27: rg-anper | R27: vpn-access-to-sql-anper | S27: southeastasia | T27: { "Organization Name": "PT Nawa Darsana Teknologi", "Publisher": "Microsoft", "Publisher Customer ID": "346fa229-7c19-44ef-85c6-29e00edf66cf", "Unit Price": "157.52", "ERP": "128880.0", "BenefitType": "Charge", "Anper": "CE" } | U27: Organization Name=PT Nawa Darsana Teknologi; Publisher=Microsoft; Publisher Customer ID=346fa229-7c19-44ef-85c6-29e00edf66cf; Unit Price=157.52; ERP=128880.0; BenefitType=Charge; Anper=CE | V27: 7 | W27: 128880 | X27: 113414.4 | Y27: -15465.6 | Z27: 128880 | AA27: 0.13636364
A28: June | B28: Microsoft CSP Azure Plan | C28: Divisi Inovasi | D28: divisiinovasi.onmicrosoft.com | E28: a4cdaa2e-caa7-440f-b849-928a3ceb7e31 | F28: AzureCSP_DivisiInovasi | G28: 1141685 | H28: VM RI | I28: Virtual Machines | J28: Virtual Machines RI | K28: Standard | L28: 46174 | M28: 46203 | N28: 25.919699 | O28: 1 Hour | P28: IDR | Q28: MC_RG-ANPER_APRICOT_SOUTHEASTASIA | R28: aks-usereph2-32489559-vmss | S28: southeastasia | T28: { "Organization Name": "PT Nawa Darsana Teknologi", "Publisher": "Microsoft", "Publisher Customer ID": "346fa229-7c19-44ef-85c6-29e00edf66cf", "Unit Price": "0.0", "ERP": "0.0", "BenefitType": "Charge", "aks-managed-consolidated-additional-properties": "74465425-495d-11f1-ad6b-a26c3881ebea", "aks-managed-creationSource": "vmssclient-aks-usereph2-32489559-vmss", "aks-managed-enable-imds-restriction": "False", "aks-managed-kubeletIdentityClientID": "c9e56520-a8a3-452c-b5ca-cb3192dafd24", "aks-managed-operationID": "7a36d094-d16e-4088-b1a9-83b67397ae99", "aks-managed-orchestrator": "Kubernetes:1.33.5", "aks-managed-poolName": "usereph2", "aks-managed-resourceNameSuffix": "14784282.0", "aks-managed-ssh-access": "LocalUser", "compute.aks.billing": "linux" } | U28: Organization Name=PT Nawa Darsana Teknologi; Publisher=Microsoft; Publisher Customer ID=346fa229-7c19-44ef-85c6-29e00edf66cf; Unit Price=0.0; ERP=0.0; BenefitType=Charge; aks-managed-consolidated-additional-properties=74465425-495d-11f1-ad6b-a26c3881ebea; aks-managed-creationSource=vmssclient-aks-usereph2-32489559-vmss; aks-managed-enable-imds-restriction=False; aks-managed-kubeletIdentityClientID=c9e56520-a8a3-452c-b5ca-cb3192dafd24; aks-managed-operationID=7a36d094-d16e-4088-b1a9-83b67397ae99; aks-managed-orchestrator=Kubernetes:1.33.5; aks-managed-poolName=usereph2; aks-managed-resourceNameSuffix=14784282.0; aks-managed-ssh-access=LocalUser; compute.aks.billing=linux | V28: 16 | W28: 0 | X28: 0 | Y28: 0 | Z28: 0
A29: June | B29: Microsoft CSP Azure Plan | C29: Divisi Inovasi | D29: divisiinovasi.onmicrosoft.com | E29: a4cdaa2e-caa7-440f-b849-928a3ceb7e31 | F29: AzureCSP_DivisiInovasi | G29: 1141685 | H29: VM RI | I29: Virtual Machines | J29: Virtual Machines RI | K29: Standard | L29: 46174 | M29: 46203 | N29: 231.99937 | O29: 1 Hour | P29: IDR | Q29: MC_RG-ANPER_APRICOT_SOUTHEASTASIA | R29: aks-usereph2-32489559-vmss | S29: southeastasia | T29: { "Organization Name": "PT Nawa Darsana Teknologi", "Publisher": "Microsoft", "Publisher Customer ID": "346fa229-7c19-44ef-85c6-29e00edf66cf", "Unit Price": "0.0", "ERP": "0.0", "BenefitType": "Charge", "aks-managed-consolidated-additional-properties": "74465425-495d-11f1-ad6b-a26c3881ebea", "aks-managed-creationSource": "vmssclient-aks-usereph2-32489559-vmss", "aks-managed-enable-imds-restriction": "False", "aks-managed-kubeletIdentityClientID": "c9e56520-a8a3-452c-b5ca-cb3192dafd24", "aks-managed-operationID": "7a36d094-d16e-4088-b1a9-83b67397ae99", "aks-managed-orchestrator": "Kubernetes:1.33.5", "aks-managed-poolName": "usereph2", "aks-managed-resourceNameSuffix": "14784282.0", "aks-managed-ssh-access": "LocalUser", "compute.aks.billing": "linux" } | U29: Organization Name=PT Nawa Darsana Teknologi; Publisher=Microsoft; Publisher Customer ID=346fa229-7c19-44ef-85c6-29e00edf66cf; Unit Price=0.0; ERP=0.0; BenefitType=Charge; aks-managed-consolidated-additional-properties=74465425-495d-11f1-ad6b-a26c3881ebea; aks-managed-creationSource=vmssclient-aks-usereph2-32489559-vmss; aks-managed-enable-imds-restriction=False; aks-managed-kubeletIdentityClientID=c9e56520-a8a3-452c-b5ca-cb3192dafd24; aks-managed-operationID=7a36d094-d16e-4088-b1a9-83b67397ae99; aks-managed-orchestrator=Kubernetes:1.33.5; aks-managed-poolName=usereph2; aks-managed-resourceNameSuffix=14784282.0; aks-managed-ssh-access=LocalUser; compute.aks.billing=linux | V29: 16 | W29: 0 | X29: 0 | Y29: 0 | Z29: 0
A30: June | B30: Microsoft CSP Azure Plan | C30: Divisi Inovasi | D30: divisiinovasi.onmicrosoft.com | E30: a4cdaa2e-caa7-440f-b849-928a3ceb7e31 | F30: AzureCSP_DivisiInovasi | G30: 1141685 | H30: Bd Inter-Rgn | I30: Bandwidth | J30: Bandwidth Inter-Region | K30: Inter Continent Data Transfer Out - ASIA To Any | L30: 46174 | M30: 46203 | N30: 2.0574184 | O30: 1 GB | P30: IDR | Q30: mc_rg-anper_apricot_southeastasia | R30: aks-usereph2-32489559-vmss | S30: southeastasia | T30: { "Organization Name": "PT Nawa Darsana Teknologi", "Publisher": "Microsoft", "Publisher Customer ID": "346fa229-7c19-44ef-85c6-29e00edf66cf", "Unit Price": "1216.4071829961", "ERP": "2946.22315954", "BenefitType": "Charge", "aks-managed-consolidated-additional-properties": "74465425-495d-11f1-ad6b-a26c3881ebea", "aks-managed-creationSource": "vmssclient-aks-usereph2-32489559-vmss", "aks-managed-enable-imds-restriction": "False", "aks-managed-kubeletIdentityClientID": "c9e56520-a8a3-452c-b5ca-cb3192dafd24", "aks-managed-operationID": "7a36d094-d16e-4088-b1a9-83b67397ae99", "aks-managed-orchestrator": "Kubernetes:1.33.5", "aks-managed-poolName": "usereph2", "aks-managed-resourceNameSuffix": "14784282.0", "aks-managed-ssh-access": "LocalUser", "compute.aks.billing": "linux" } | U30: Organization Name=PT Nawa Darsana Teknologi; Publisher=Microsoft; Publisher Customer ID=346fa229-7c19-44ef-85c6-29e00edf66cf; Unit Price=1216.4071829961; ERP=2946.22315954; BenefitType=Charge; aks-managed-consolidated-additional-properties=74465425-495d-11f1-ad6b-a26c3881ebea; aks-managed-creationSource=vmssclient-aks-usereph2-32489559-vmss; aks-managed-enable-imds-restriction=False; aks-managed-kubeletIdentityClientID=c9e56520-a8a3-452c-b5ca-cb3192dafd24; aks-managed-operationID=7a36d094-d16e-4088-b1a9-83b67397ae99; aks-managed-orchestrator=Kubernetes:1.33.5; aks-managed-poolName=usereph2; aks-managed-resourceNameSuffix=14784282.0; aks-managed-ssh-access=LocalUser; compute.aks.billing=linux | V30: 16 | W30: 2843.9285 | X30: 2502.6585 | Y30: -341.27 | Z30: 2843.9285 | AA30: 0.13636299
A31: June | B31: Microsoft CSP Azure Plan | C31: Divisi Inovasi | D31: divisiinovasi.onmicrosoft.com | E31: a4cdaa2e-caa7-440f-b849-928a3ceb7e31 | F31: AzureCSP_DivisiInovasi | G31: 1141685 | H31: Virtual Network Peering | I31: Virtual Network | J31: Virtual Network Peering | K31: Intra-Region Ingress | L31: 46174 | M31: 46203 | N31: 1.0353796 | O31: 1 GB | P31: IDR | Q31: mc_rg-anper_apricot_southeastasia | R31: aks-usereph2-32489559-vmss | S31: southeastasia | T31: { "Organization Name": "PT Nawa Darsana Teknologi", "Publisher": "Microsoft", "Publisher Customer ID": "346fa229-7c19-44ef-85c6-29e00edf66cf", "Unit Price": "157.5199999971", "ERP": "185.33295556", "BenefitType": "Charge", "aks-managed-consolidated-additional-properties": "74465425-495d-11f1-ad6b-a26c3881ebea", "aks-managed-creationSource": "vmssclient-aks-usereph2-32489559-vmss", "aks-managed-enable-imds-restriction": "False", "aks-managed-kubeletIdentityClientID": "c9e56520-a8a3-452c-b5ca-cb3192dafd24", "aks-managed-operationID": "7a36d094-d16e-4088-b1a9-83b67397ae99", "aks-managed-orchestrator": "Kubernetes:1.33.5", "aks-managed-poolName": "usereph2", "aks-managed-resourceNameSuffix": "14784282.0", "aks-managed-ssh-access": "LocalUser", "compute.aks.billing": "linux" } | U31: Organization Name=PT Nawa Darsana Teknologi; Publisher=Microsoft; Publisher Customer ID=346fa229-7c19-44ef-85c6-29e00edf66cf; Unit Price=157.5199999971; ERP=185.33295556; BenefitType=Charge; aks-managed-consolidated-additional-properties=74465425-495d-11f1-ad6b-a26c3881ebea; aks-managed-creationSource=vmssclient-aks-usereph2-32489559-vmss; aks-managed-enable-imds-restriction=False; aks-managed-kubeletIdentityClientID=c9e56520-a8a3-452c-b5ca-cb3192dafd24; aks-managed-operationID=7a36d094-d16e-4088-b1a9-83b67397ae99; aks-managed-orchestrator=Kubernetes:1.33.5; aks-managed-poolName=usereph2; aks-managed-resourceNameSuffix=14784282.0; aks-managed-ssh-access=LocalUser; compute.aks.billing=linux | V31: 16 | W31: 185.333 | X31: 163.093 | Y31: -22.24 | Z31: 185.333 | AA31: 0.13636391
A32: June | B32: Microsoft CSP Azure Plan | C32: Divisi Inovasi | D32: divisiinovasi.onmicrosoft.com | E32: a4cdaa2e-caa7-440f-b849-928a3ceb7e31 | F32: AzureCSP_DivisiInovasi | G32: 1141685 | H32: Bd Inter-Rgn | I32: Bandwidth | J32: Bandwidth Inter-Region | K32: Intra Continent Data Transfer Out | L32: 46174 | M32: 46203 | N32: 4.9221726 | O32: 1 GB | P32: IDR | Q32: mc_rg-anper_apricot_southeastasia | R32: aks-usereph2-32489559-vmss | S32: southeastasia | T32: { "Organization Name": "PT Nawa Darsana Teknologi", "Publisher": "Microsoft", "Publisher Customer ID": "346fa229-7c19-44ef-85c6-29e00edf66cf", "Unit Price": "1260.1599999994", "ERP": "7048.55117573", "BenefitType": "Charge", "aks-managed-consolidated-additional-properties": "74465425-495d-11f1-ad6b-a26c3881ebea", "aks-managed-creationSource": "vmssclient-aks-usereph2-32489559-vmss", "aks-managed-enable-imds-restriction": "False", "aks-managed-kubeletIdentityClientID": "c9e56520-a8a3-452c-b5ca-cb3192dafd24", "aks-managed-operationID": "7a36d094-d16e-4088-b1a9-83b67397ae99", "aks-managed-orchestrator": "Kubernetes:1.33.5", "aks-managed-poolName": "usereph2", "aks-managed-resourceNameSuffix": "14784282.0", "aks-managed-ssh-access": "LocalUser", "compute.aks.billing": "linux" } | U32: Organization Name=PT Nawa Darsana Teknologi; Publisher=Microsoft; Publisher Customer ID=346fa229-7c19-44ef-85c6-29e00edf66cf; Unit Price=1260.1599999994; ERP=7048.55117573; BenefitType=Charge; aks-managed-consolidated-additional-properties=74465425-495d-11f1-ad6b-a26c3881ebea; aks-managed-creationSource=vmssclient-aks-usereph2-32489559-vmss; aks-managed-enable-imds-restriction=False; aks-managed-kubeletIdentityClientID=c9e56520-a8a3-452c-b5ca-cb3192dafd24; aks-managed-operationID=7a36d094-d16e-4088-b1a9-83b67397ae99; aks-managed-orchestrator=Kubernetes:1.33.5; aks-managed-poolName=usereph2; aks-managed-resourceNameSuffix=14784282.0; aks-managed-ssh-access=LocalUser; compute.aks.billing=linux | V32: 16 | W32: 7048.555 | X32: 6202.725 | Y32: -845.83 | Z32: 7048.555 | AA32: 0.13636426
A33: June | B33: Microsoft CSP Azure Plan | C33: Divisi Inovasi | D33: divisiinovasi.onmicrosoft.com | E33: a4cdaa2e-caa7-440f-b849-928a3ceb7e31 | F33: AzureCSP_DivisiInovasi | G33: 1141685 | H33: Logic Apps | I33: Logic Apps | J33: Logic Apps | K33: Consumption Data Retention | L33: 46174 | M33: 46203 | N33: 0.046663639 | O33: 1 GB/Month | P33: IDR | Q33: RG-ANPER | R33: CURL-API-ANPER | S33: indonesiacentral | T33: { "Organization Name": "PT Nawa Darsana Teknologi", "Publisher": "Microsoft", "Publisher Customer ID": "346fa229-7c19-44ef-85c6-29e00edf66cf", "Unit Price": "2211.5807999223", "ERP": "117.27319071", "BenefitType": "Charge" } | U33: Organization Name=PT Nawa Darsana Teknologi; Publisher=Microsoft; Publisher Customer ID=346fa229-7c19-44ef-85c6-29e00edf66cf; Unit Price=2211.5807999223; ERP=117.27319071; BenefitType=Charge | V33: 6 | W33: 117.27041 | X33: 103.20041 | Y33: -14.07 | Z33: 117.27041 | AA33: 0.13633667
A34: June | B34: Microsoft CSP Azure Plan | C34: Divisi Inovasi | D34: divisiinovasi.onmicrosoft.com | E34: a4cdaa2e-caa7-440f-b849-928a3ceb7e31 | F34: AzureCSP_DivisiInovasi | G34: 1141685 | H34: Virtual Network Private Link | I34: Virtual Network | J34: Virtual Network Private Link | K34: Standard Data Processed - Egress | L34: 46174 | M34: 46203 | N34: 4.6731e-05 | O34: 1 GB | P34: IDR | Q34: mc_rg-anper_apricot_southeastasia | R34: aks-usereph2-32489559-vmss | S34: southeastasia | T34: { "Organization Name": "PT Nawa Darsana Teknologi", "Publisher": "Microsoft", "Publisher Customer ID": "346fa229-7c19-44ef-85c6-29e00edf66cf", "Unit Price": "157.519996421", "ERP": "0.00836467", "BenefitType": "Charge", "aks-managed-consolidated-additional-properties": "74465425-495d-11f1-ad6b-a26c3881ebea", "aks-managed-creationSource": "vmssclient-aks-usereph2-32489559-vmss", "aks-managed-enable-imds-restriction": "False", "aks-managed-kubeletIdentityClientID": "c9e56520-a8a3-452c-b5ca-cb3192dafd24", "aks-managed-operationID": "7a36d094-d16e-4088-b1a9-83b67397ae99", "aks-managed-orchestrator": "Kubernetes:1.33.5", "aks-managed-poolName": "usereph2", "aks-managed-resourceNameSuffix": "14784282.0", "aks-managed-ssh-access": "LocalUser", "compute.aks.billing": "linux" } | U34: Organization Name=PT Nawa Darsana Teknologi; Publisher=Microsoft; Publisher Customer ID=346fa229-7c19-44ef-85c6-29e00edf66cf; Unit Price=157.519996421; ERP=0.00836467; BenefitType=Charge; aks-managed-consolidated-additional-properties=74465425-495d-11f1-ad6b-a26c3881ebea; aks-managed-creationSource=vmssclient-aks-usereph2-32489559-vmss; aks-managed-enable-imds-restriction=False; aks-managed-kubeletIdentityClientID=c9e56520-a8a3-452c-b5ca-cb3192dafd24; aks-managed-operationID=7a36d094-d16e-4088-b1a9-83b67397ae99; aks-managed-orchestrator=Kubernetes:1.33.5; aks-managed-poolName=usereph2; aks-managed-resourceNameSuffix=14784282.0; aks-managed-ssh-access=LocalUser; compute.aks.billing=linux | V34: 16 | W34: 0.0073610627 | X34: 0.0073610627 | Y34: 0 | Z34: 0.0073610627 | AA34: 0
A35: June | B35: Microsoft CSP Azure Plan | C35: Divisi Inovasi | D35: divisiinovasi.onmicrosoft.com | E35: a4cdaa2e-caa7-440f-b849-928a3ceb7e31 | F35: AzureCSP_DivisiInovasi | G35: 1141685 | H35: Virtual Network Private Link | I35: Virtual Network | J35: Virtual Network Private Link | K35: Standard Data Processed - Ingress | L35: 46174 | M35: 46203 | N35: 0.04001391 | O35: 1 GB | P35: IDR | Q35: rg-anper | R35: vpn-access-to-sql-anper | S35: southeastasia | T35: { "Organization Name": "PT Nawa Darsana Teknologi", "Publisher": "Microsoft", "Publisher Customer ID": "346fa229-7c19-44ef-85c6-29e00edf66cf", "Unit Price": "157.5199999604", "ERP": "7.16248989", "BenefitType": "Charge", "Anper": "CE" } | U35: Organization Name=PT Nawa Darsana Teknologi; Publisher=Microsoft; Publisher Customer ID=346fa229-7c19-44ef-85c6-29e00edf66cf; Unit Price=157.5199999604; ERP=7.16248989; BenefitType=Charge; Anper=CE | V35: 7 | W35: 7.1629911 | X35: 6.3029911 | Y35: -0.86 | Z35: 7.1629911 | AA35: 0.13644316
A36: June | B36: Microsoft CSP Azure Plan | C36: Divisi Inovasi | D36: divisiinovasi.onmicrosoft.com | E36: a4cdaa2e-caa7-440f-b849-928a3ceb7e31 | F36: AzureCSP_DivisiInovasi | G36: 1141685 | H36: SQL RI | I36: SQL Database | J36: SQL Database Compute Reservation | K36: Usage | L36: 46174 | M36: 46203 | N36: 192 | O36: 1 Hour | P36: IDR | Q36: RG-ANPER | R36: apitalawu | S36: southeastasia | T36: { "Organization Name": "PT Nawa Darsana Teknologi", "Publisher": "Microsoft", "Publisher Customer ID": "346fa229-7c19-44ef-85c6-29e00edf66cf", "Unit Price": "0.0", "ERP": "0.0", "BenefitType": "Charge", "Anper": "CE", "MD": "Apricot", "Product": "CE" } | U36: Organization Name=PT Nawa Darsana Teknologi; Publisher=Microsoft; Publisher Customer ID=346fa229-7c19-44ef-85c6-29e00edf66cf; Unit Price=0.0; ERP=0.0; BenefitType=Charge; Anper=CE; MD=Apricot; Product=CE | V36: 9 | W36: 0 | X36: 0 | Y36: 0 | Z36: 0
